Workbook

Sheet 12-13
E1: Saison 12/13
A2: Spieler | C2: Spiele bisher | D2: Freundschaftsspiele | R2: Pokalspiele | X2: Punktspiele | CB2: Anzahl
D3: I | E3: I | F3: I | G3: I | H3: I | I3: I | J3: I | K3: I | L3: I | M3: I | N3: I | R3: II | S3: I | T3: I | U3: I | V3: I | X3: I | Y3: I | Z3: I | AA3: I | AB3: I | AC3: II | AD3: I | AE3: II | AF3: II | AG3: I | AH3: I | AI3: II | AJ3: I | AK3: II | AL3: I | AM3: I | AN3: II | AO3: I | AP3: II | AQ3: I | AR3: II | AS3: I | AT3: II | AU3: I | AV3: II | AW3: I | AX3: I | AY3: I | AZ3: II | BA3: I | BB3: II | BC3: I | BD3: II | BE3: I | BF3: II | BG3: I | BH3: II | BI3: I | BJ3: I | BK3: II | BL3: I | BM3: II | BN3: I | BO3: II | BP3: I | BQ3: II | BR3: I | BT3: I | BU3: II
D4: Obereschach | E4: Fischbach | F4: Kappel | G4: Lackendorf | H4: Wurmlingen | I4: Schonach | K4: Tore Vorbereitung 1. Mannschaft | S4: Seedorf I | U4: Tore Pokalspiele 1. Mannschaft | X4: 19.08.2012 SG MaLo I : SV Herrenzimmern I | Y4: 22.08.2012 VfB Bösingen II : SG MaLo I | Z4: 26.08.2012 SG MaLo I : SV Beffendorf I | AA4: 02.09.2012 SV Rötenberg : SG MaLo I | AB4: 09.09.2012 SG MaLo I : SV Winzeln I | AC4: 09.09.2012 SV Winzeln II : SG MaLo II | AD4: 13.09.2012 FV Aichhalden : SG MaLo I | AE4: 16.09.23012 SG MaLo II : FC Dunningen II | AF4: 20.09.2012 Spvgg Stetten-Lackendorf II : SG MaLo II | AG4: 22.09.2012 SG MaLo I : SV Horgen I | AH4: 30.09.2012 FC Dunningen I : SG MaLo I | AI4: 30.09.2012 SG MaLo II : SV Horgen II | AJ4: 07.10.2012 SG MaLo I : TSV Böhringen I | AK4: 07.10.2012 SV Sulgen II : SG MaLo II | AL4: 14.10.2012 FC Dietingen I : SG MaLo I | AM4: 21.10.2012 SG MaLo I : FSV Zepfenhan I | AN4: 21.10.2012 SG MaLo II : SV Waldmössingen II | AO4: 28.10.2012 Türk SV Schramberg I : SG MaLo I | AP4: 28.10.2012 SV Seedorf III : SG MaLo II | AQ4: 04.11.2012 SG MaLo I : Spvgg Oberndorf I | AR4: 04.11.2012 SG MaLo II : FV Aichhalden II | AS4: 11.11.2012 FV Kickers Lauterbach I : SG MaLo I | AT4: 11.11.2012 FV Kickers Lauterbach II : SG MaLo II | AU4: 18.11.2012 SV Herrenzimmern I : SG MaLo I | AV4: 18.11.2012 SV Rötenberg II : SG MaLo II | AW4: 24.11.2012 SG MaLo I : VfB Bösingen II | AX4: 10.03.2013 SV Beffendorf I : SG MaLo I | AY4: 17.03.2013 SG MaLo I : SV Rötenberg I | AZ4: 17.03.2013 SG MaLo II : SV Winzeln II | BA4: 24.03.2013 SV Winzeln I : SG MaLo I | BB4: 24.03.2013 FC Dunningen II : SG MaLo II | BC4: 30.03.2013 2013 SG MaLo I : FV Aichhalden I | BD4: 07.04.2013 SG MaLo II : Spvgg Stetten-Lackendorf II | BE4: 14.04.2013 SV Horgen I : SG MaLo I | BF4: 14.04.2013 SV Horgen II : SG MaLo II | BG4: 21.04.2013 SG MaLo I : FC Dunningen I | BH4: 21.04.2013 SG MaLo II : SV Sulgen II | BI4: 28.04.2013 TSV Böhringen I : SG MaLo I | BJ4: 05.05.2013 SG MaLo I : FC Dietingen I | BK4: 05.05.2013 SV Waldmössingen II : SG MaLo II | BL4: 12.05.2013 FSV Zepfenhan I : SG MaLo I | BM4: 12.05.2013 SG MaLo II : SV Seedorf III | BN4: 26.05.2013 SG MaLo I : Türk SV Schramberg I | BO4: 26.05.2013 FV Aichhalden II : SG MaLo II | BP4: 02.06.2013 Spvgg Oberndorf I : SG MaLo I | BQ4: 02.06.2013 SG MaLo II : FV Kickers Lauterbach II | BR4: 09.06.2013 SG MaLo I : FV Kickers Lauterbach I | BS4: Relegation gegen Rottweil | BT4: Tore 1. Mannschaft | BU4: Tore 2. Mannschaft | CB4: Punktspiele I | CC4: Punktspiele II | CD4: Punktspiele I+II | CE4: Tore Punktspiele I | CF4: Tore Punktspiele II | CG4: Tore Punktspiele I+II | CH4: Freundschaftssp. | CI4: Tore Freundschaftssp. | CJ4: Spiele | CK4: Tore | CL4: Spiele gesamt
A5: Aichele Thomas | B5: L | C5: 109 | D5: 0 | E5: 0 | F5: 0 | G5: 0 | H5: 0 | I5: 0 | K5: 2 | S5: 0 | X5: 0 | Y5: 0 | AA5: 0 | AB5: 0 | AD5: 0 | AG5: 0 | AH5: 0 | AJ5: 0 | BA5: 0 | BJ5: 0 | BN5: 0 | BP5: 0 | BR5: 0 | BS5: 0 | BT5: 3 | CB5: 14 | CC5: 0 | CD5: 14 | CE5: 3 | CF5: 0 | CG5: 3 | CH5: 8 | CI5: 2 | CJ5: 22 | CK5: 5 | CL5: 131
A6: Auber A. | B6: M | C6: 379 | CB6: 0 | CC6: 0 | CD6: 0 | CE6: 0 | CF6: 0 | CG6: 0 | CH6: 0 | CI6: 0 | CJ6: 0 | CK6: 0 | CL6: 379
A7: Augstein M | B7: L | C7: 75 | CB7: 0 | CC7: 0 | CD7: 0 | CE7: 0 | CF7: 0 | CG7: 0 | CH7: 0 | CI7: 0 | CJ7: 0 | CK7: 0 | CL7: 75
A8: Bannert Dirk | B8: L | C8: 60 | CB8: 0 | CC8: 0 | CD8: 0 | CE8: 0 | CF8: 0 | CG8: 0 | CH8: 0 | CI8: 0 | CJ8: 0 | CK8: 0 | CL8: 60
A9: Bekir Kilic | B9: L | C9: 63 | CB9: 0 | CC9: 0 | CD9: 0 | CE9: 0 | CF9: 0 | CG9: 0 | CH9: 0 | CI9: 0 | CJ9: 0 | CK9: 0 | CL9: 63
A10: Binnig Andre | B10: L | C10: 13 | D10: 0 | E10: 0 | F10: 0 | H10: 0 | I10: 0 | S10: 0 | X10: 0 | Y10: 0 | Z10: 0 | AA10: 0 | AB10: 0 | AD10: 0 | AG10: 0 | AH10: 0 | AJ10: 0 | AL10: 0 | AM10: 0 | AQ10: 0 | AS10: 0 | AU10: 0 | AW10: 0 | AX10: 0 | AY10: 0 | BA10: 0 | BC10: 0 | BE10: 0 | BG10: 0 | BI10: 0 | CB10: 22 | CC10: 0 | CD10: 22 | CE10: 0 | CF10: 0 | CG10: 0 | CH10: 6 | CI10: 0 | CJ10: 28 | CK10: 0 | CL10: 41
A11: Bosch M. | B11: L | C11: 118 | D11: 0 | E11: 0 | F11: 0 | G11: 0 | H11: 0 | I11: 0 | K11: 1 | S11: 0 | X11: 0 | Y11: 0 | Z11: 0 | AA11: 0 | AB11: 0 | AD11: 0 | AG11: 0 | AH11: 0 | AJ11: 0 | AL11: 0 | AM11: 0 | AQ11: 0 | AS11: 0 | AU11: 0 | AW11: 0 | AX11: 0 | AY11: 0 | BA11: 0 | BC11: 0 | BE11: 0 | BG11: 0 | BI11: 0 | BJ11: 0 | BN11: 0 | BT11: 3 | CB11: 25 | CC11: 0 | CD11: 25 | CE11: 3 | CF11: 0 | CG11: 3 | CH11: 8 | CI11: 1 | CJ11: 33 | CK11: 4 | CL11: 151
A12: Broghammer Michael | B12: M | C12: 10 | CB12: 0 | CC12: 0 | CD12: 0 | CE12: 0 | CF12: 0 | CG12: 0 | CH12: 0 | CI12: 0 | CJ12: 0 | CK12: 0 | CL12: 10
A13: Czerny A | B13: M | C13: 206 | CB13: 0 | CC13: 0 | CD13: 0 | CE13: 0 | CF13: 0 | CG13: 0 | CH13: 0 | CI13: 0 | CJ13: 0 | CK13: 0 | CL13: 206
A14: Dold Markus | B14: M | C14: 7 | D14: 0 | E14: 0 | F14: 0 | H14: 0 | I14: 0 | X14: 0 | Y14: 0 | Z14: 0 | AB14: 0 | AD14: 0 | AH14: 0 | AJ14: 0 | AU14: 0 | AW14: 0 | CB14: 9 | CC14: 0 | CD14: 9 | CE14: 0 | CF14: 0 | CG14: 0 | CH14: 5 | CI14: 0 | CJ14: 14 | CK14: 0 | CL14: 21
A15: Ebert D. | B15: M | C15: 373 | CB15: 0 | CC15: 0 | CD15: 0 | CE15: 0 | CF15: 0 | CG15: 0 | CH15: 0 | CI15: 0 | CJ15: 0 | CK15: 0 | CL15: 373
A16: Ebert M. | B16: M | C16: 143 | D16: 0 | E16: 0 | F16: 0 | S16: 0 | AA16: 0 | AB16: 0 | AD16: 0 | AG16: 0 | AS16: 0 | AU16: 0 | AY16: 0 | BA16: 0 | BC16: 0 | BE16: 0 | BG16: 0 | BI16: 0 | BJ16: 0 | BL16: 0 | BN16: 0 | BP16: 0 | BS16: 0 | BT16: 2 | CB16: 17 | CC16: 0 | CD16: 17 | CE16: 2 | CF16: 0 | CG16: 2 | CH16: 4 | CI16: 0 | CJ16: 21 | CK16: 2 | CL16: 164
A17: Engesser M. | B17: M | C17: 161 | D17: 0 | E17: 0 | I17: 0 | S17: 0 | AA17: 0 | AB17: 0 | CB17: 2 | CC17: 0 | CD17: 2 | CE17: 0 | CF17: 0 | CG17: 0 | CH17: 4 | CI17: 0 | CJ17: 6 | CK17: 0 | CL17: 167
A18: Ganter F. | B18: M | C18: 380 | CB18: 0 | CC18: 0 | CD18: 0 | CE18: 0 | CF18: 0 | CG18: 0 | CH18: 0 | CI18: 0 | CJ18: 0 | CK18: 0 | CL18: 380
A19: Glase Rico | B19: M | C19: 27 | CB19: 0 | CC19: 0 | CD19: 0 | CE19: 0 | CF19: 0 | CG19: 0 | CH19: 0 | CI19: 0 | CJ19: 0 | CK19: 0 | CL19: 27
A20: Günter Ralf | B20: L | C20: 70 | E20: 0 | G20: 0 | H20: 0 | I20: 0 | S20: 0 | X20: 0 | Z20: 0 | AS20: 0 | AU20: 0 | AW20: 0 | BG20: 0 | BI20: 0 | BJ20: 0 | BP20: 0 | BQ20: 0 | BT20: 1 | CB20: 10 | CC20: 1 | CD20: 11 | CE20: 1 | CF20: 0 | CG20: 1 | CH20: 5 | CI20: 0 | CJ20: 16 | CK20: 1 | CL20: 86
A21: Haberstroh Benny | B21: M | C21: 16 | CB21: 0 | CC21: 0 | CD21: 0 | CE21: 0 | CF21: 0 | CG21: 0 | CH21: 0 | CI21: 0 | CJ21: 0 | CK21: 0 | CL21: 16
A22: Haberstroh Michael | B22: M | C22: 3 | CB22: 0 | CC22: 0 | CD22: 0 | CE22: 0 | CF22: 0 | CG22: 0 | CH22: 0 | CI22: 0 | CJ22: 0 | CK22: 0 | CL22: 3
A23: Haberstroh Raphael | B23: M | C23: 46 | D23: 0 | E23: 0 | F23: 0 | G23: 0 | H23: 0 | I23: 0 | S23: 0 | Y23: 0 | Z23: 0 | AA23: 0 | AB23: 0 | AH23: 0 | AJ23: 0 | AL23: 0 | AM23: 0 | AU23: 0 | AW23: 0 | AX23: 0 | AY23: 0 | BA23: 0 | BC23: 0 | BE23: 0 | BG23: 0 | BI23: 0 | BJ23: 0 | BL23: 0 | BN23: 0 | BS23: 0 | BT23: 1 | CB23: 21 | CC23: 0 | CD23: 21 | CE23: 1 | CF23: 0 | CG23: 1 | CH23: 7 | CI23: 0 | CJ23: 28 | CK23: 1 | CL23: 74
A24: Heilmann M. | B24: M | C24: 243 | CB24: 0 | CC24: 0 | CD24: 0 | CE24: 0 | CF24: 0 | CG24: 0 | CH24: 0 | CI24: 0 | CJ24: 0 | CK24: 0 | CL24: 243
A25: Hornikel A. | B25: M | C25: 336 | CB25: 0 | CC25: 0 | CD25: 0 | CE25: 0 | CF25: 0 | CG25: 0 | CH25: 0 | CI25: 0 | CJ25: 0 | CK25: 0 | CL25: 336
A26: Jäckle M. | B26: M | C26: 274 | CB26: 0 | CC26: 0 | CD26: 0 | CE26: 0 | CF26: 0 | CG26: 0 | CH26: 0 | CI26: 0 | CJ26: 0 | CK26: 0 | CL26: 274
A27: Jaki S. | B27: M | C27: 417 | D27: 0 | E27: 0 | F27: 0 | G27: 0 | I27: 0 | K27: 6 | X27: 0 | Y27: 0 | Z27: 0 | AD27: 0 | AG27: 0 | AH27: 0 | AJ27: 0 | AL27: 0 | AQ27: 0 | AS27: 0 | AX27: 0 | AY27: 0 | BA27: 0 | BC27: 0 | BE27: 0 | BN27: 0 | BO27: 0 | BR27: 0 | BS27: 0 | BT27: 10 | CB27: 18 | CC27: 1 | CD27: 19 | CE27: 10 | CF27: 0 | CG27: 10 | CH27: 6 | CI27: 6 | CJ27: 25 | CK27: 16 | CL27: 442
A28: Jauch Jo. | B28: M | C28: 334 | G28: 0 | H28: 0 | I28: 0 | X28: 0 | Y28: 0 | Z28: 0 | AA28: 0 | AB28: 0 | AD28: 0 | CB28: 6 | CC28: 0 | CD28: 6 | CE28: 0 | CF28: 0 | CG28: 0 | CH28: 3 | CI28: 0 | CJ28: 9 | CK28: 0 | CL28: 343
A29: Jauch Jürgen | B29: M | C29: 214 | CB29: 0 | CC29: 0 | CD29: 0 | CE29: 0 | CF29: 0 | CG29: 0 | CH29: 0 | CI29: 0 | CJ29: 0 | CK29: 0 | CL29: 214
A30: Klausmann M. | B30: M | C30: 253 | CB30: 0 | CC30: 0 | CD30: 0 | CE30: 0 | CF30: 0 | CG30: 0 | CH30: 0 | CI30: 0 | CJ30: 0 | CK30: 0 | CL30: 253
A31: Klein Daniel | B31: M | C31: 106 | AG31: 0 | AH31: 0 | AJ31: 0 | AL31: 0 | AM31: 0 | AQ31: 0 | AS31: 0 | AU31: 0 | AX31: 0 | AY31: 0 | BA31: 0 | BC31: 0 | BE31: 0 | BG31: 0 | BI31: 0 | BJ31: 0 | BL31: 0 | BN31: 0 | BP31: 0 | BR31: 0 | BS31: 0 | CB31: 20 | CC31: 0 | CD31: 20 | CE31: 0 | CF31: 0 | CG31: 0 | CH31: 0 | CI31: 0 | CJ31: 20 | CK31: 0 | CL31: 126
A32: Linder Andreas | B32: L | C32: 35 | CB32: 0 | CC32: 0 | CD32: 0 | CE32: 0 | CF32: 0 | CG32: 0 | CH32: 0 | CI32: 0 | CJ32: 0 | CK32: 0 | CL32: 35
A33: Löffler Marius | B33: L | C33: 28 | E33: 0 | F33: 0 | G33: 0 | H33: 0 | K33: 1 | X33: 0 | Y33: 0 | Z33: 0 | AA33: 0 | AB33: 0 | AD33: 0 | AG33: 0 | AJ33: 0 | AL33: 0 | AM33: 0 | AQ33: 0 | AS33: 0 | AU33: 0 | AW33: 0 | AY33: 0 | BC33: 0 | BE33: 0 | BG33: 0 | BI33: 0 | BJ33: 0 | BP33: 0 | BR33: 0 | BT33: 1 | CB33: 23 | CC33: 0 | CD33: 23 | CE33: 1 | CF33: 0 | CG33: 1 | CH33: 5 | CI33: 1 | CJ33: 28 | CK33: 2 | CL33: 56
A34: Marte Marvin | B34: M | C34: 40 | D34: 0 | E34: 0 | F34: 0 | G34: 0 | H34: 0 | S34: 0 | X34: 0 | Y34: 0 | Z34: 0 | AA34: 0 | AB34: 0 | AD34: 0 | AG34: 0 | AH34: 0 | AJ34: 0 | AL34: 0 | AM34: 0 | AQ34: 0 | AS34: 0 | AU34: 0 | AX34: 0 | AY34: 0 | BC34: 0 | BE34: 0 | BG34: 0 | BI34: 0 | BJ34: 0 | BL34: 0 | BN34: 0 | BP34: 0 | BR34: 0 | BS34: 0 | BT34: 4 | CB34: 26 | CC34: 0 | CD34: 26 | CE34: 4 | CF34: 0 | CG34: 4 | CH34: 6 | CI34: 0 | CJ34: 32 | CK34: 4 | CL34: 72
A35: Moosmann J. | B35: L | C35: 40 | D35: 0 | E35: 0 | F35: 0 | G35: 0 | H35: 0 | AB35: 0 | AD35: 0 | AJ35: 0 | AL35: 0 | AM35: 0 | AQ35: 0 | AS35: 0 | AX35: 0 | BA35: 0 | BC35: 0 | BE35: 0 | BG35: 0 | BI35: 0 | BJ35: 0 | BL35: 0 | BN35: 0 | BP35: 0 | BR35: 0 | BS35: 0 | CB35: 18 | CC35: 0 | CD35: 18 | CE35: 0 | CF35: 0 | CG35: 0 | CH35: 5 | CI35: 0 | CJ35: 23 | CK35: 0 | CL35: 63
A36: Moosmann M. | B36: M | C36: 351 | CB36: 0 | CC36: 0 | CD36: 0 | CE36: 0 | CF36: 0 | CG36: 0 | CH36: 0 | CI36: 0 | CJ36: 0 | CK36: 0 | CL36: 351
A37: Müller Thorsten | B37: M | C37: 6 | CB37: 0 | CC37: 0 | CD37: 0 | CE37: 0 | CF37: 0 | CG37: 0 | CH37: 0 | CI37: 0 | CJ37: 0 | CK37: 0 | CL37: 6
A38: Müller-Kohl, Ricardo | B38: M | C38: 4 | CB38: 0 | CC38: 0 | CD38: 0 | CE38: 0 | CF38: 0 | CG38: 0 | CH38: 0 | CI38: 0 | CJ38: 0 | CK38: 0 | CL38: 4
A39: Murer Matthias | B39: L | C39: 151 | E39: 0 | F39: 0 | G39: 0 | H39: 0 | I39: 0 | S39: 0 | X39: 0 | Y39: 0 | Z39: 0 | AA39: 0 | AB39: 0 | AD39: 0 | AG39: 0 | AJ39: 0 | AL39: 0 | AM39: 0 | AQ39: 0 | AS39: 0 | AW39: 0 | AX39: 0 | AY39: 0 | BA39: 0 | BC39: 0 | BE39: 0 | BG39: 0 | BI39: 0 | BL39: 0 | BP39: 0 | BR39: 0 | BS39: 0 | BT39: 1 | CB39: 24 | CC39: 0 | CD39: 24 | CE39: 1 | CF39: 0 | CG39: 1 | CH39: 6 | CI39: 0 | CJ39: 30 | CK39: 1 | CL39: 181
A40: Oehler Alex | B40: L | C40: 24 | CB40: 0 | CC40: 0 | CD40: 0 | CE40: 0 | CF40: 0 | CG40: 0 | CH40: 0 | CI40: 0 | CJ40: 0 | CK40: 0 | CL40: 24
...

Sheet 13-14
E1: Saison 13/14
A2: Spieler | C2: Spiele bisher | D2: Freundschaftsspiele | R2: Pokalspiele | X2: Punktspiele | CB2: Anzahl
F3: I | G3: I | H3: I | I3: I | J3: I | R3: I | S3: I | T3: I | U3: II | V3: II | W3: II | X3: I | Y3: I | Z3: I | AA3: I | AB3: I | AC3: I | AD3: I | AE3: I | AF3: I | AG3: I | AH3: I | AI3: I | AJ3: I | AK3: I | AL3: I | AM3: I | AN3: I | AO3: I | AP3: I | AQ3: I | AR3: I | AS3: I | AT3: I | AU3: I | AV3: I | AW3: I | AX3: I | AY3: I | AZ3: I | BA3: I | BE3: II | BF3: II | BG3: II | BH3: II | BI3: II | BJ3: II | BK3: II | BL3: II | BM3: II | BN3: II | BO3: II | BP3: II | BQ3: II | BR3: II | BS3: II | BT3: II | BU3: II | BV3: II
F4: 28.07.2013 SpVgg Schiltach : SG MaLo I | G4: 03.08.2013 SG MaLo I : SpVgg Oberndorf | H4: 11.08.2013 SG MaLo - FC Schonach | I4: 18.08.2013 SV Niedereschach - SG MaLo | J4: 22.02.2014 Spvgg Stetten-Lackendorf - SG MaLo | R4: 28.08.2013 Spvgg Oberndorf - SG MaLo | S4: 03.10.2013 SV Herrenzimmern - SG MaLo | T4: 21.04.2014 SG MaLo - SV Irslingen | U4: 28.08.2013 SG MaLo - SV Gosheim | V4: 01.10.2013 FC Dunningen - SG MaLo | W4: 20.03.2014 SG MaLo - SV Wurmlingen | X4: 18.08.2013 Spielfrei | Y4: 21.08.2013 SGMaLo I - FSV Schwenningen | Z4: 25.08.2013 SV Winzeln SG MaLo | AA4: 01.09.2013 SG MaLa - SV Beffendorf | AB4: 08.09.2013 SV Sulgen - SG MaLo | AC4: 15.09.2013 SG MaLo - FV Aichhalden | AD4: 19.09.2013 FC Dunningen - SG MaLo | AE4: 22.09.2013 SG MaLo - FV08 Rottweil II | AF4: 28.09.2013 FV Diestingen - SG MaLo | AG4: 06.10.2013 SG MaLo - SV Herrenzimmern | AH4: 13.10.2013 FSV Zepfenhahn - SG MaLo | AI4: 01.11.2013 SG MaLo - FV Kickers Lauterbach | AJ4: 03.04.2014 SV Horgen - SG MaLo | AK4: 03.11.2013 SG MaLo - SV Zimmern | AL4: 16.03.2014 SV Rötenberg - SG MaLo | AM4: 17.11.2013 Spielfrei | AN4: 23.11.2013FSV Schwenningen - SG MaLo | AO4: 23.03.2014 SG MaLo - SV Winzeln | AP4: 30.03.2014 SV Beffendorf - SG MaLo | AQ4: 06.04.2014 SG MaLo - SV Sulgen | AR4: 13.04.2014 FV Aichhalden - SG MaLo | AS4: 19.04.2014 SG MaLo - FC Dunningen | AT4: 27.04.2014 FV08 Rottweil II - SG MaLo | AU4: 30.04.2014 SG MaLo - FC Dietingen | AV4: 04.05.2014 SV Herrenzimmern - SG MaLo | AW4: 11.05.2014 SG MaLo - FSV Zepfenhan | AX4: 18.05.2014 FV Kickers Lauterbach - SG MaLo | AY4: 25.05.2014 SG MaLo - SV Horgen | AZ4: 01.06.2014 SV Zimmern - SG MaLo | BA4: 07.06.2014 SG MaLo - SV Rötenberg | BE4: 15.09.2013 SG MaLo - SV Winzeln | BF4: 22.09.2013 Spvgg. Stetten-Lackendorf - SG MaLo | BG4: 28.09.2013 SV Seedorf III - SG MaLo | BH4: 06.10.2013 SG MaLo - FV Aichhalden | BI4: 13.10.2013 FC Dunningen - SG MaLo | BJ4: 17.04.2014 SG MaLo - AV Herrenzimmern | BK4: 17.11.2013 FV Kickers Lauterbach - SG MaLo | BL4: 19.04.2014 SG MaLo - SV Horgen | BM4: 30.03.2014 SV Rötenberg - SG MaLo | BN4: 06.04.2014 SV Winzeln - SG MaLo | BO4: 13.04.2014 SG MaLo - Spvgg Stetten Lackendorf | BP4: 26.04.2014 SG MaLo - SV Seedorf | BQ4: 04.05.2014 FV Aichhalden - SG MaLo | BR4: 11.05.2014 SG MaLo - FC Dunningen | BS4: 18.05.2014 SV Herrenzimmern SG MaLo | BT4: 25.05.2014 SG MaLo - FV Kickers Lauterbach | BU4: 01.06.2014 SV Horgen - SG MaLo | BV4: 07.06.2014 SG MaLo - SV Rötenberg | CB4: Punktspiele I | CC4: Punktspiele II | CD4: Punktspiele I+II | CE4: Tore Punktspiele I | CF4: Tore Punktspiele II | CG4: Tore Punktspiele I+II | CH4: Freundschaftssp. | CI4: Tore Freundschaftssp. | CJ4: Spiele | CK4: Tore | CL4: Spiele gesamt
A5: Aichele Thomas | B5: L | C5: 131 | CB5: 0 | CC5: 0 | CD5: 0 | CE5: 0 | CF5: 0 | CG5: 0 | CH5: 0 | CI5: 0 | CJ5: 0 | CK5: 0 | CL5: 131
A6: Auber Armin | H6: 0 | U6: 0 | BE6: 0 | BF6: 0 | BG6: 0 | BL6: 1 | BN6: 0 | BO6: 0 | CB6: 0 | CC6: 6 | CD6: 6 | CE6: 0 | CF6: 1 | CG6: 1 | CH6: 2 | CI6: 0 | CJ6: 8 | CK6: 1 | CL6: 8
A7: Auber Axel | B7: M | C7: 379 | CB7: 0 | CC7: 0 | CD7: 0 | CE7: 0 | CF7: 0 | CG7: 0 | CH7: 0 | CI7: 0 | CJ7: 0 | CK7: 0 | CL7: 379
A8: Augstein M | B8: L | C8: 75 | U8: 0 | BE8: 0 | BF8: 0 | CB8: 0 | CC8: 2 | CD8: 2 | CE8: 0 | CF8: 0 | CG8: 0 | CH8: 1 | CI8: 0 | CJ8: 3 | CK8: 0 | CL8: 78
A9: Bannert Dirk | B9: L | C9: 60 | CB9: 0 | CC9: 0 | CD9: 0 | CE9: 0 | CF9: 0 | CG9: 0 | CH9: 0 | CI9: 0 | CJ9: 0 | CK9: 0 | CL9: 60
A10: Bekir Kilic | B10: L | C10: 63 | BL10: 0 | CB10: 0 | CC10: 1 | CD10: 1 | CE10: 0 | CF10: 0 | CG10: 0 | CH10: 0 | CI10: 0 | CJ10: 1 | CK10: 0 | CL10: 64
A11: Benner, Florian | F11: 0 | H11: 0 | J11: 0 | R11: 0 | S11: 0 | T11: 0 | Y11: 0 | Z11: 0 | AA11: 0 | AB11: 0 | AC11: 0 | AD11: 0 | AE11: 0 | AF11: 0 | AG11: 0 | AH11: 0 | AI11: 0 | AJ11: 0 | AK11: 0 | AN11: 0 | AP11: 0 | AQ11: 0 | AR11: 0 | AS11: 0 | AT11: 0 | AU11: 0 | AV11: 0 | CB11: 21 | CC11: 0 | CD11: 21 | CE11: 0 | CF11: 0 | CG11: 0 | CH11: 6 | CI11: 0 | CJ11: 27 | CK11: 0 | CL11: 27
A12: Binnig Andre | B12: L | C12: 41 | F12: 0 | I12: 0 | R12: 0 | S12: 0 | T12: 0 | AA12: 0 | AI12: 0 | AJ12: 0 | AK12: 0 | AL12: 0 | AN12: 0 | AP12: 0 | AQ12: 0 | AR12: 0 | BG12: 0 | BH12: 0 | BI12: 0 | BQ12: 0 | CB12: 9 | CC12: 4 | CD12: 13 | CE12: 0 | CF12: 0 | CG12: 0 | CH12: 5 | CI12: 0 | CJ12: 18 | CK12: 0 | CL12: 59
A13: Bosch M. | B13: L | C13: 151 | F13: 0 | H13: 0 | I13: 0 | J13: 1 | R13: 1 | T13: 1 | V13: 0 | W13: 0 | Y13: 0 | Z13: 0 | AA13: 0 | AD13: 0 | AF13: 0 | AH13: 0 | AI13: 0 | AJ13: 0 | AK13: 0 | AN13: 0 | AP13: 0 | AR13: 0 | AS13: 0 | AT13: 0 | AU13: 0 | AV13: 0 | BE13: 0 | BF13: 0 | BH13: 2 | CB13: 16 | CC13: 3 | CD13: 19 | CE13: 0 | CF13: 2 | CG13: 2 | CH13: 8 | CI13: 3 | CJ13: 27 | CK13: 5 | CL13: 178
A14: Broghammer Michael | B14: M | C14: 10 | H14: 0 | BE14: 0 | BG14: 0 | CB14: 0 | CC14: 2 | CD14: 2 | CE14: 0 | CF14: 0 | CG14: 0 | CH14: 1 | CI14: 0 | CJ14: 3 | CK14: 0 | CL14: 13
A15: Coraci Davide | U15: 0 | V15: 0 | W15: 0 | BE15: 0 | BF15: 0 | BG15: 0 | BI15: 0 | BJ15: 0 | BL15: 0 | BM15: 0 | BO15: 0 | BP15: 0 | BQ15: 0 | CB15: 0 | CC15: 10 | CD15: 10 | CE15: 0 | CF15: 0 | CG15: 0 | CH15: 3 | CI15: 0 | CJ15: 13 | CK15: 0 | CL15: 13
A16: Czerny A | B16: M | C16: 206 | U16: 0 | W16: 0 | BE16: 0 | BF16: 0 | BH16: 0 | BJ16: 0 | BK16: 0 | BM16: 0 | BO16: 0 | BP16: 0 | CB16: 0 | CC16: 8 | CD16: 8 | CE16: 0 | CF16: 0 | CG16: 0 | CH16: 2 | CI16: 0 | CJ16: 10 | CK16: 0 | CL16: 216
A17: Dereck Christian | S17: 0 | W17: 0 | AH17: 0 | AI17: 0 | AK17: 0 | AN17: 0 | BE17: 0 | BF17: 0 | BG17: 0 | BH17: 0 | BJ17: 0 | BK17: 0 | BM17: 0 | BN17: 0 | BO17: 0 | BQ17: 0 | CB17: 4 | CC17: 10 | CD17: 14 | CE17: 0 | CF17: 0 | CG17: 0 | CH17: 2 | CI17: 0 | CJ17: 16 | CK17: 0 | CL17: 16
A18: Dold Markus | B18: M | C18: 21 | J18: 0 | R18: 0 | T18: 0 | V18: 0 | Y18: 0 | Z18: 0 | AA18: 0 | AB18: 0 | AC18: 0 | AE18: 0 | AF18: 0 | AG18: 0 | AH18: 0 | AI18: 0 | AJ18: 0 | AK18: 0 | AL18: 1 | AN18: 1 | AP18: 0 | AQ18: 1 | AR18: 0 | AS18: 0 | AU18: 0 | AV18: 0 | CB18: 20 | CC18: 0 | CD18: 20 | CE18: 3 | CF18: 0 | CG18: 3 | CH18: 4 | CI18: 0 | CJ18: 24 | CK18: 3 | CL18: 45
A19: Ebert D. | B19: M | C19: 373 | H19: 0 | BG19: 0 | BI19: 0 | BL19: 0 | BN19: 0 | CB19: 0 | CC19: 4 | CD19: 4 | CE19: 0 | CF19: 0 | CG19: 0 | CH19: 1 | CI19: 0 | CJ19: 5 | CK19: 0 | CL19: 378
A20: Ebert M. | B20: M | C20: 164 | H20: 0 | I20: 0 | S20: 0 | T20: 0 | Y20: 0 | AC20: 0 | AD20: 0 | AF20: 0 | AG20: 0 | AI20: 1 | AJ20: 0 | AL20: 0 | AN20: 0 | AP20: 0 | AQ20: 0 | AS20: 0 | AT20: 0 | AU20: 0 | AV20: 0 | CB20: 15 | CC20: 0 | CD20: 15 | CE20: 1 | CF20: 0 | CG20: 1 | CH20: 4 | CI20: 0 | CJ20: 19 | CK20: 1 | CL20: 183
A21: Engesser M. | B21: M | C21: 167 | CB21: 0 | CC21: 0 | CD21: 0 | CE21: 0 | CF21: 0 | CG21: 0 | CH21: 0 | CI21: 0 | CJ21: 0 | CK21: 0 | CL21: 167
A22: Ettwein Kevin | V22: 0 | BE22: 0 | BH22: 0 | BI22: 0 | BK22: 0 | CB22: 0 | CC22: 4 | CD22: 4 | CE22: 0 | CF22: 0 | CG22: 0 | CH22: 1 | CI22: 0 | CJ22: 5 | CK22: 0 | CL22: 5
A23: Ettwein Dennis | H23: 0 | J23: 0 | S23: 0 | U23: 0 | V23: 0 | W23: 0 | BE23: 0 | BG23: 0 | BH23: 0 | BK23: 0 | BQ23: 0 | CB23: 0 | CC23: 5 | CD23: 5 | CE23: 0 | CF23: 0 | CG23: 0 | CH23: 6 | CI23: 0 | CJ23: 11 | CK23: 0 | CL23: 11
A24: Ganter F. | B24: M | C24: 380 | AH24: 0 | BK24: 0 | CB24: 1 | CC24: 1 | CD24: 2 | CE24: 0 | CF24: 0 | CG24: 0 | CH24: 0 | CI24: 0 | CJ24: 2 | CK24: 0 | CL24: 382
A25: Glase Rico | B25: M | C25: 27 | BH25: 0 | BO25: 0 | BP25: 0 | CB25: 0 | CC25: 3 | CD25: 3 | CE25: 0 | CF25: 0 | CG25: 0 | CH25: 0 | CI25: 0 | CJ25: 3 | CK25: 0 | CL25: 30
A26: Günter Ralf | B26: L | C26: 86 | F26: 0 | H26: 0 | I26: 0 | J26: 0 | R26: 0 | T26: 0 | Y26: 0 | Z26: 0 | AA26: 0 | AB26: 0 | AI26: 0 | AJ26: 0 | AK26: 0 | AL26: 0 | AN26: 0 | AP26: 1 | AQ26: 0 | AS26: 0 | AT26: 0 | BI26: 0 | CB26: 13 | CC26: 1 | CD26: 14 | CE26: 1 | CF26: 0 | CG26: 1 | CH26: 6 | CI26: 0 | CJ26: 20 | CK26: 1 | CL26: 106
A27: Haberstroh Benny | B27: M | C27: 16 | CB27: 0 | CC27: 0 | CD27: 0 | CE27: 0 | CF27: 0 | CG27: 0 | CH27: 0 | CI27: 0 | CJ27: 0 | CK27: 0 | CL27: 16
A28: Haberstroh Michael | B28: M | C28: 3 | CB28: 0 | CC28: 0 | CD28: 0 | CE28: 0 | CF28: 0 | CG28: 0 | CH28: 0 | CI28: 0 | CJ28: 0 | CK28: 0 | CL28: 3
A29: Haberstroh Raphael | B29: M | C29: 74 | F29: 0 | I29: 0 | J29: 0 | R29: 0 | T29: 0 | V29: 3 | W29: 1 | Y29: 0 | Z29: 0 | AA29: 0 | AB29: 0 | AC29: 0 | AD29: 0 | AE29: 0 | AF29: 0 | AG29: 0 | AH29: 0 | AS29: 0 | AT29: 0 | AU29: 0 | AV29: 0 | BJ29: 1 | BL29: 0 | BM29: 2 | BO29: 0 | BP29: 0 | CB29: 14 | CC29: 5 | CD29: 19 | CE29: 0 | CF29: 3 | CG29: 3 | CH29: 7 | CI29: 4 | CJ29: 26 | CK29: 7 | CL29: 100
A30: Heilmann M. | B30: M | C30: 243 | CB30: 0 | CC30: 0 | CD30: 0 | CE30: 0 | CF30: 0 | CG30: 0 | CH30: 0 | CI30: 0 | CJ30: 0 | CK30: 0 | CL30: 243
A31: Hornikel A. | B31: M | C31: 336 | CB31: 0 | CC31: 0 | CD31: 0 | CE31: 0 | CF31: 0 | CG31: 0 | CH31: 0 | CI31: 0 | CJ31: 0 | CK31: 0 | CL31: 336
A32: Jäckle M. | B32: M | C32: 274 | CB32: 0 | CC32: 0 | CD32: 0 | CE32: 0 | CF32: 0 | CG32: 0 | CH32: 0 | CI32: 0 | CJ32: 0 | CK32: 0 | CL32: 274
A33: Jaki S. | B33: M | C33: 442 | H33: 0 | U33: 1 | BE33: 3 | BF33: 1 | BG33: 2 | BI33: 0 | BJ33: 0 | BK33: 0 | BO33: 0 | BP33: 0 | CB33: 0 | CC33: 8 | CD33: 8 | CE33: 0 | CF33: 6 | CG33: 6 | CH33: 2 | CI33: 1 | CJ33: 10 | CK33: 7 | CL33: 452
A34: Jauch Jo. | B34: M | C34: 343 | CB34: 0 | CC34: 0 | CD34: 0 | CE34: 0 | CF34: 0 | CG34: 0 | CH34: 0 | CI34: 0 | CJ34: 0 | CK34: 0 | CL34: 343
A35: Jauch Jürgen | B35: M | C35: 214 | CB35: 0 | CC35: 0 | CD35: 0 | CE35: 0 | CF35: 0 | CG35: 0 | CH35: 0 | CI35: 0 | CJ35: 0 | CK35: 0 | CL35: 214
A36: Klausmann M. | B36: M | C36: 253 | CB36: 0 | CC36: 0 | CD36: 0 | CE36: 0 | CF36: 0 | CG36: 0 | CH36: 0 | CI36: 0 | CJ36: 0 | CK36: 0 | CL36: 253
A37: Klein Daniel | B37: M | C37: 126 | F37: 0 | H37: 0 | T37: 0 | U37: 0 | V37: 0 | Y37: 0 | Z37: 0 | BE37: 0 | BF37: 0 | BG37: 0 | BH37: 0 | BI37: 0 | BK37: 0 | BL37: 0 | BM37: 0 | BN37: 0 | BO37: 0 | BP37: 0 | BQ37: 0 | CB37: 2 | CC37: 12 | CD37: 14 | CE37: 0 | CF37: 0 | CG37: 0 | CH37: 5 | CI37: 0 | CJ37: 19 | CK37: 0 | CL37: 145
A38: Linder Andreas | B38: L | C38: 35 | W38: 0 | BH38: 0 | BI38: 0 | BJ38: 0 | BL38: 0 | BM38: 0 | BN38: 0 | BO38: 0 | BP38: 0 | BQ38: 0 | CB38: 0 | CC38: 9 | CD38: 9 | CE38: 0 | CF38: 0 | CG38: 0 | CH38: 1 | CI38: 0 | CJ38: 10 | CK38: 0 | CL38: 45
A39: Löffler Marius | B39: L | C39: 56 | F39: 0 | H39: 0 | I39: 0 | J39: 0 | R39: 1 | T39: 0 | V39: 0 | Y39: 0 | Z39: 2 | AA39: 0 | AB39: 0 | AC39: 0 | AD39: 0 | AE39: 0 | AF39: 0 | AG39: 0 | AH39: 0 | AI39: 0 | AJ39: 0 | AK39: 0 | AL39: 1 | AN39: 0 | AP39: 0 | AQ39: 0 | AR39: 0 | AS39: 0 | AT39: 0 | AU39: 0 | AV39: 0 | CB39: 22 | CC39: 0 | CD39: 22 | CE39: 3 | CF39: 0 | CG39: 3 | CH39: 7 | CI39: 1 | CJ39: 29 | CK39: 4 | CL39: 85
A40: Marte Marvin | B40: M | C40: 72 | F40: 0 | I40: 0 | J40: 0 | R40: 0 | S40: 0 | Y40: 0 | Z40: 1 | AA40: 0 | AB40: 0 | AC40: 0 | AD40: 1 | AE40: 0 | AF40: 0 | AG40: 0 | AI40: 0 | AJ40: 0 | AK40: 0 | AL40: 0 | AN40: 0 | AP40: 0 | AQ40: 1 | AR40: 0 | AT40: 0 | AU40: 0 | AV40: 0 | CB40: 20 | CC40: 0 | CD40: 20 | CE40: 3 | CF40: 0 | CG40: 3 | CH40: 5 | CI40: 0 | CJ40: 25 | CK40: 3 | CL40: 97
...

Sheet 14-15
E1: Saison 14/15
A2: Spieler | C2: Spiele bisher | D2: Freundschaftsspiele | R2: Pokalspiele | X2: Punktspiele | CB2: Anzahl
D3: I | E3: I | F3: I | G3: I | H3: I | I3: I | J3: I | L3: II | M3: II | N3: II | O3: II | P3: II | Q3: II | R3: II | T3: I | U3: II | V3: II | X3: I | Y3: I | Z3: I | AA3: I | AB3: I | AC3: I | AD3: I | AE3: I | AF3: I | AG3: I | AH3: I | AI3: I | AJ3: I | AK3: I | AL3: I | AM3: I | AN3: I | AO3: I | AP3: I | AQ3: I | AR3: I | AS3: I | AT3: I | AU3: I | AV3: I | AW3: I | AX3: I | AY3: I | AZ3: I | BA3: I | BE3: II | BF3: II | BG3: II | BH3: II | BI3: II | BJ3: II | BK3: II | BL3: II | BM3: II | BN3: II | BO3: II | BP3: II | BQ3: II | BR3: II | BS3: II | BT3: II | BU3: II | BV3: II | BW3: II | BX3: II | BY3: II | BZ3: II
D4: Fr, 18.07.14 SGM Locherhof/Mariazell : FC Neuhausen | E4: Mi, 23.07.14 SGM Locherhof/Mariazell : SV Schapbach | F4: Sa, 09.08.14 SGM Locherhof/Mariazell : FV Tennenbronn 2 | G4: SGM Locherhof/Mariazell : FV Tennenbronn (abgesagt) | H4: Sa, 21.02.15 SV Schapbach : SGM Locherhof/Mariazell | I4: Mi, 04.03.15 FV Tennenbronn 2 : SGM Locherhof/Mariazell | J4: Di, 10.03.15 FC Kirnbach : SGM Locherhof/Mariazell | L4: So, 03.08.14 SGM Locherhof/Mariazell II : FC Epfendorf II | M4: So, 10.08.14 SGM Locherhof/Mariazell II : Spvgg Bochingen II | N4: Mi, 13.08.14 SGM Locherhof/Mariazell II : FV Kickers Lauterbach II | O4: So, 31.08.14 SGM Locherhof/Mariazell II : SV Horgen II | P4: So, 22.02.15 SGM Locherhof/Mariazell II : FC Epfendorf II (abg.) | Q4: So, 08.03.15 FV Kickers Lauterbach II : SGM Locherhof/Mariazell II | R4: So, 15.03.15 SGM Locherhof/Mariazell II : Spvgg Bochingen II (abg.) | T4: Sa, 16.08.14 SGM Locherhof/Mariazell : SV Villingendorf | U4: Mi, 03.09.14 SGM Locherhof/Mariazell II : SV Fridingen | V4: Mi, 08.10.14 SGM Locherhof/Mariazell II : SGM Aichhalden/Rötenberg | X4: So, 24.08.14 SGM Locherhof/Mariazell : SV Horgen | Y4: Mi, 27.08.14 SV Irslingen : SGM Locherhof/Mariazell | Z4: So, 31.08.14 SGM Locherhof/Mariazell : SGM Aichhalden/Rötenberg | AA4: Sa, 06.09.14 SV Beffendorf : SGM Locherhof/Mariazell | AB4: So, 14.09.14 SGM Locherhof/Mariazell : SV Herrenzimmern | AC4: Do, 18.09.14 FSV Zepfenhan : SGM Locherhof/Mariazell | AD4: So, 21.09.14 SGM Locherhof/Mariazell : FC Hardt | AE4: So, 28.09.14 SV Zimmern o.R. II : SGM Locherhof/Mariazell | AF4: So, 05.10.14 FV Kickers Lauterbach : SGM Locherhof/Mariazell | AG4: So, 12.10.14 SGM Locherhof/Mariazell : FC Dietingen | AH4: So, 19.10.14 SC Lindenhof : SGM Locherhof/Mariazell | AI4: So, 26.10.14 SGM Locherhof/Mariazell : FV 08 Rottweil II | AJ4: So, 02.11.14 TG Rottweil-Altstadt : SGM Locherhof/Mariazell | AK4: So, 09.11.14 SGM Locherhof/Mariazell : SV Winzeln | AL4: So, 16.11.14 Spvgg Stetten-Lackendorf : SGM Locherhof/Mariazell | AM4: Fr, 21.11.14 SV Horgen : SGM Locherhof/Mariazell | AN4: So, 30.11.14 SGM Locherhof/Mariazell : SV Irslingen | AO4: So, 15.03.15 SGM Aichhalden/Rötenberg : SGM Locherhof/Mariazell | AP4: So, 22.03.15 SGM Locherhof/Mariazell : SV Beffendorf | AQ4: So, 29.03.15 SV Herrenzimmern : SGM Locherhof/Mariazell | AR4: Sa, 04.04.15 SGM Locherhof/Mariazell : FSV Zepfenhan | AS4: So, 12.04.15 FC Hardt : SGM Locherhof/Mariazell | AT4: So, 19.04.15 SGM Locherhof/Mariazell : SV Zimmern o.R. II | AU4: So, 26.04.15 SGM Locherhof/Mariazell : FV Kickers Lauterbach | AV4: So, 03.05.15 FC Dietingen : SGM Locherhof/Mariazell | AW4: So, 10.05.15 SGM Locherhof/Mariazell : SC Lindenhof | AX4: So, 17.05.15 FV 08 Rottweil II : SGM Locherhof/Mariazell | AY4: Sa, 23.05.15 SGM Locherhof/Mariazell : TG Rottweil-Altstadt | AZ4: So, 31.05.15 SV Winzeln : SGM Locherhof/Mariazell | BA4: So, 07.06.15 SGM Locherhof/Mariazell : Spvgg Stetten-Lackendorf | BE4: So, 07.09.14 SGM Locherhof/Mariazell II : SV Herrenzimmern II | BF4: So, 14.09.14 SV Winzeln II : SGM Locherhof/Mariazell II | BG4: So, 21.09.14 SGM Locherhof/Mariazell II : FC Hardt II | BH4: So, 28.09.14 Spvgg Stetten-Lackendorf II : SGM Locherhof/Mariazell II | BI4: So, 05.10.14 SGM Locherhof/Mariazell II : SV Sulgen II | BJ4: So, 12.10.14 FC Dunningen II : SGM Locherhof/Mariazell II | BK4: So, 19.10.14 SC Lindenhof II : SGM Locherhof/Mariazell II | BL4: Sa, 25.10.14 SGM Beffendorf/Bösingen : SGM Locherhof/Mariazell II | BM4: So, 02.11.14 SGM Locherhof/Mariazell II : Spvgg Oberndorf II | BN4: So, 09.11.14 SGM Locherhof/Mariazell II : Türk SV Schramberg | BO4: So, 16.11.14 SGM Aichhalden/Rötenberg III : SGM Locherhof/Mariazell II | BP4: Sa, 22.11.14 SV Herrenzimmern II : SGM Locherhof/Mariazell II | BQ4: So, 22.03.15 SGM Locherhof/Mariazell II : SV Winzeln II | BR4: So, 29.03.15 FC Hardt II : SGM Locherhof/Mariazell II | BS4: So, 12.04.15 SGM Locherhof/Mariazell II : Spvgg Stetten-Lackendorf II | BT4: So, 19.04.15 SV Sulgen II : SGM Locherhof/Mariazell II | BU4: So, 26.04.15 SGM Locherhof/Mariazell II : FC Dunningen II | BV4: So, 03.05.15 SGM Locherhof/Mariazell II : SC Lindenhof II | BW4: Mi, 20.05.15 SGM Locherhof/Mariazell II : SGM Beffendorf/Bösingen | BX4: So, 17.05.15 Spvgg Oberndorf II : SGM Locherhof/Mariazell II | BY4: So, 31.05.15 Türk SV Schramberg : SGM Locherhof/Mariazell II | BZ4: So, 07.06.15 SGM Locherhof/Mariazell II : SGM Aichhalden/Rötenberg III | CB4: Punktspiele I | CC4: Punktspiele II | CD4: Punktspiele I+II | CE4: Tore Punktspiele I | CF4: Tore Punktspiele II | CG4: Tore Punktspiele I+II | CH4: Freundschaftssp. | CI4: Tore Freundschaftssp. | CJ4: Spiele | CK4: Tore | CL4: Spiele gesamt
A5: Aichele Thomas | B5: L | C5: 131 | CB5: 0 | CC5: 0 | CD5: 0 | CE5: 0 | CF5: 0 | CG5: 0 | CH5: 0 | CI5: 0 | CJ5: 0 | CK5: 0 | CL5: 131
A6: Auber Armin | B6: M | C6: 14 | AT6: 0 | BE6: 0 | BG6: 0 | BI6: 0 | BJ6: 0 | BQ6: 1 | BR6: 0 | BS6: 0 | BT6: 0 | CB6: 1 | CC6: 8 | CD6: 9 | CE6: 0 | CF6: 1 | CG6: 1 | CH6: 0 | CI6: 0 | CJ6: 9 | CK6: 1 | CL6: 23
A7: Auber Axel | B7: M | C7: 382 | CB7: 0 | CC7: 0 | CD7: 0 | CE7: 0 | CF7: 0 | CG7: 0 | CH7: 0 | CI7: 0 | CJ7: 0 | CK7: 0 | CL7: 382
A8: Augstein M | B8: L | C8: 265 | BZ8: 0 | CB8: 0 | CC8: 1 | CD8: 1 | CE8: 0 | CF8: 0 | CG8: 0 | CH8: 0 | CI8: 0 | CJ8: 1 | CK8: 0 | CL8: 266
A9: Bannert Dirk | B9: L | C9: 273 | CB9: 0 | CC9: 0 | CD9: 0 | CE9: 0 | CF9: 0 | CG9: 0 | CH9: 0 | CI9: 0 | CJ9: 0 | CK9: 0 | CL9: 273
A10: Bekir Kilic | B10: L | C10: 137 | CB10: 0 | CC10: 0 | CD10: 0 | CE10: 0 | CF10: 0 | CG10: 0 | CH10: 0 | CI10: 0 | CJ10: 0 | CK10: 0 | CL10: 137
A11: Benner, Florian | B11: M | C11: 37 | J11: 0 | L11: 0 | M11: 0 | Q11: 0 | AC11: 0 | AN11: 0 | BE11: 0 | BF11: 0 | BG11: 1 | BH11: 1 | BI11: 0 | BJ11: 0 | BK11: 0 | BL11: 0 | BM11: 1 | BN11: 0 | BO11: 0 | BP11: 0 | BU11: 0 | BV11: 0 | BW11: 0 | BX11: 0 | CB11: 2 | CC11: 16 | CD11: 18 | CE11: 0 | CF11: 3 | CG11: 3 | CH11: 4 | CI11: 0 | CJ11: 22 | CK11: 3 | CL11: 59
A12: Binnig Andre | B12: L | C12: 68 | D12: 0 | E12: 0 | F12: 0 | H12: 0 | L12: 0 | N12: 0 | T12: 0 | V12: 0 | X12: 0 | Y12: 0 | Z12: 0 | AA12: 0 | AB12: 0 | AC12: 0 | AD12: 0 | AM12: 0 | AN12: 0 | AY12: 0 | BA12: 0 | BH12: 0 | BI12: 0 | BJ12: 0 | BL12: 0 | BM12: 0 | BN12: 0 | BO12: 0 | BP12: 0 | BU12: 0 | BV12: 1 | BW12: 0 | BX12: 0 | BY12: 0 | CB12: 11 | CC12: 13 | CD12: 24 | CE12: 0 | CF12: 1 | CG12: 1 | CH12: 8 | CI12: 0 | CJ12: 32 | CK12: 1 | CL12: 100
A13: Bosch M. | B13: L | C13: 391 | D13: 0 | E13: 0 | F13: 0 | H13: 0 | I13: 0 | J13: 0 | L13: 0 | M13: 0 | AA13: 0 | AB13: 0 | AC13: 0 | AD13: 0 | AE13: 0 | AF13: 0 | AG13: 0 | AH13: 0 | AI13: 0 | AJ13: 0 | AK13: 0 | AL13: 0 | AM13: 0 | AO13: 0 | AP13: 0 | AQ13: 0 | AR13: 0 | AW13: 0 | BW13: 0 | BY13: 0 | BZ13: 0 | CB13: 18 | CC13: 3 | CD13: 21 | CE13: 0 | CF13: 0 | CG13: 0 | CH13: 8 | CI13: 0 | CJ13: 29 | CK13: 0 | CL13: 420
A14: Broghammer Michael | B14: M | C14: 25 | CB14: 0 | CC14: 0 | CD14: 0 | CE14: 0 | CF14: 0 | CG14: 0 | CH14: 0 | CI14: 0 | CJ14: 0 | CK14: 0 | CL14: 25
A15: Coraci Davide | B15: L | C15: 25 | L15: 0 | M15: 0 | O15: 2 | Q15: 0 | T15: 0 | V15: 1 | BE15: 0 | BF15: 0 | BH15: 0 | BI15: 0 | BK15: 1 | BL15: 0 | BM15: 0 | BN15: 0 | BP15: 0 | BZ15: 0 | CB15: 0 | CC15: 10 | CD15: 10 | CE15: 0 | CF15: 1 | CG15: 1 | CH15: 6 | CI15: 3 | CJ15: 16 | CK15: 4 | CL15: 41
A16: Czerny A | B16: M | C16: 218 | V16: 0 | BF16: 0 | BJ16: 0 | BO16: 0 | BS16: 0 | BT16: 0 | BX16: 0 | BY16: 0 | BZ16: 0 | CB16: 0 | CC16: 8 | CD16: 8 | CE16: 0 | CF16: 0 | CG16: 0 | CH16: 1 | CI16: 0 | CJ16: 9 | CK16: 0 | CL16: 227
A17: Dereck Christian | B17: M | C17: 25 | L17: 0 | M17: 0 | O17: 0 | Q17: 0 | V17: 0 | AT17: 0 | AU17: 0 | BA17: 0 | BE17: 0 | BF17: 0 | BG17: 1 | BH17: 2 | BI17: 0 | BK17: 0 | BL17: 0 | BM17: 1 | BN17: 0 | BP17: 0 | BQ17: 0 | BR17: 0 | BS17: 2 | BV17: 0 | BW17: 0 | BX17: 0 | BY17: 0 | CB17: 3 | CC17: 17 | CD17: 20 | CE17: 0 | CF17: 6 | CG17: 6 | CH17: 5 | CI17: 0 | CJ17: 25 | CK17: 6 | CL17: 50
A18: Dold Markus | B18: M | C18: 56 | D18: 0 | E18: 0 | F18: 0 | H18: 0 | I18: 0 | J18: 0 | X18: 0 | Y18: 0 | Z18: 1 | AA18: 0 | AB18: 0 | AC18: 0 | AD18: 0 | AE18: 0 | AF18: 0 | AG18: 0 | AH18: 0 | AI18: 0 | AJ18: 0 | AK18: 0 | AL18: 0 | AM18: 0 | AN18: 0 | AO18: 0 | AP18: 0 | AQ18: 0 | AS18: 0 | AT18: 1 | AU18: 0 | AV18: 0 | AW18: 0 | AX18: 0 | AY18: 1 | AZ18: 0 | CB18: 28 | CC18: 0 | CD18: 28 | CE18: 3 | CF18: 0 | CG18: 3 | CH18: 6 | CI18: 0 | CJ18: 34 | CK18: 3 | CL18: 90
A19: Ebert D. | B19: M | C19: 383 | BQ19: 0 | BZ19: 0 | CB19: 0 | CC19: 2 | CD19: 2 | CE19: 0 | CF19: 0 | CG19: 0 | CH19: 0 | CI19: 0 | CJ19: 2 | CK19: 0 | CL19: 385
A20: Ebert M. | B20: M | C20: 199 | H20: 0 | I20: 0 | J20: 0 | L20: 0 | N20: 0 | Q20: 0 | T20: 0 | X20: 0 | Y20: 0 | AA20: 0 | AB20: 0 | AC20: 0 | AD20: 0 | AE20: 1 | AF20: 0 | AG20: 0 | AH20: 0 | AI20: 0 | AJ20: 0 | AK20: 0 | AL20: 0 | AM20: 0 | AN20: 0 | AO20: 0 | AP20: 0 | AQ20: 0 | AR20: 0 | AS20: 0 | AU20: 0 | AV20: 0 | AW20: 0 | AX20: 0 | AY20: 0 | AZ20: 1 | BA20: 0 | CB20: 28 | CC20: 0 | CD20: 28 | CE20: 2 | CF20: 0 | CG20: 2 | CH20: 7 | CI20: 0 | CJ20: 35 | CK20: 2 | CL20: 234
A21: Engesser M. | B21: M | C21: 167 | CB21: 0 | CC21: 0 | CD21: 0 | CE21: 0 | CF21: 0 | CG21: 0 | CH21: 0 | CI21: 0 | CJ21: 0 | CK21: 0 | CL21: 167
A22: Ettwein Kevin | B22: L | C22: 8 | CB22: 0 | CC22: 0 | CD22: 0 | CE22: 0 | CF22: 0 | CG22: 0 | CH22: 0 | CI22: 0 | CJ22: 0 | CK22: 0 | CL22: 8
A23: Ettwein Dennis | B23: L | C23: 27 | L23: 0 | M23: 0 | N23: 0 | O23: 0 | BE23: 0 | CB23: 0 | CC23: 1 | CD23: 1 | CE23: 0 | CF23: 0 | CG23: 0 | CH23: 4 | CI23: 0 | CJ23: 5 | CK23: 0 | CL23: 32
A24: Ganter F. | B24: M | C24: 400 | BJ24: 0 | CB24: 0 | CC24: 1 | CD24: 1 | CE24: 0 | CF24: 0 | CG24: 0 | CH24: 0 | CI24: 0 | CJ24: 1 | CK24: 0 | CL24: 401
A25: Glase Rico | B25: M | C25: 40 | Q25: 0 | CB25: 0 | CC25: 0 | CD25: 0 | CE25: 0 | CF25: 0 | CG25: 0 | CH25: 1 | CI25: 0 | CJ25: 1 | CK25: 0 | CL25: 41
A26: Günter Ralf | B26: L | C26: 125 | D26: 0 | E26: 0 | F26: 0 | H26: 0 | I26: 0 | J26: 0 | L26: 0 | O26: 0 | AB26: 0 | AC26: 0 | AD26: 0 | AE26: 0 | AF26: 0 | AG26: 0 | AH26: 0 | AJ26: 0 | AK26: 0 | AL26: 0 | AN26: 0 | AO26: 0 | AQ26: 0 | AR26: 0 | AS26: 0 | AT26: 0 | AU26: 0 | AV26: 0 | AW26: 0 | AX26: 0 | AY26: 0 | AZ26: 0 | BE26: 0 | BL26: 0 | BN26: 0 | BP26: 0 | CB26: 22 | CC26: 4 | CD26: 26 | CE26: 0 | CF26: 0 | CG26: 0 | CH26: 8 | CI26: 0 | CJ26: 34 | CK26: 0 | CL26: 159
A27: Haberstroh Benny | B27: M | C27: 19 | CB27: 0 | CC27: 0 | CD27: 0 | CE27: 0 | CF27: 0 | CG27: 0 | CH27: 0 | CI27: 0 | CJ27: 0 | CK27: 0 | CL27: 19
A28: Haberstroh Michael | B28: M | C28: 6 | CB28: 0 | CC28: 0 | CD28: 0 | CE28: 0 | CF28: 0 | CG28: 0 | CH28: 0 | CI28: 0 | CJ28: 0 | CK28: 0 | CL28: 6
A29: Haberstroh Raphael | B29: M | C29: 112 | E29: 0 | F29: 0 | J29: 0 | M29: 0 | Q29: 0 | X29: 0 | Y29: 0 | Z29: 0 | AA29: 0 | AB29: 0 | AC29: 0 | AD29: 0 | AE29: 0 | AF29: 0 | AN29: 0 | AO29: 0 | AT29: 0 | AU29: 0 | AV29: 0 | AW29: 0 | AX29: 0 | AY29: 0 | AZ29: 0 | BA29: 0 | BK29: 1 | BL29: 0 | BM29: 1 | BN29: 0 | BO29: 1 | BR29: 0 | CB29: 19 | CC29: 6 | CD29: 25 | CE29: 0 | CF29: 3 | CG29: 3 | CH29: 5 | CI29: 0 | CJ29: 30 | CK29: 3 | CL29: 142
A30: Hauser Marcel | B30: L | C30: 1 | H30: 0 | L30: 0 | M30: 0 | O30: 0 | V30: 0 | BE30: 0 | BF30: 0 | BG30: 0 | BH30: 0 | BI30: 0 | BJ30: 0 | BK30: 0 | BM30: 0 | BN30: 0 | BO30: 0 | BP30: 0 | BQ30: 0 | BR30: 0 | BS30: 0 | BT30: 0 | BU30: 0 | BV30: 0 | BW30: 0 | BX30: 0 | BY30: 0 | BZ30: 0 | CB30: 0 | CC30: 21 | CD30: 21 | CE30: 0 | CF30: 0 | CG30: 0 | CH30: 5 | CI30: 0 | CJ30: 26 | CK30: 0 | CL30: 27
A31: Heilmann M. | B31: M | C31: 245 | CB31: 0 | CC31: 0 | CD31: 0 | CE31: 0 | CF31: 0 | CG31: 0 | CH31: 0 | CI31: 0 | CJ31: 0 | CK31: 0 | CL31: 245
A32: Hornikel A. | B32: M | C32: 339 | CB32: 0 | CC32: 0 | CD32: 0 | CE32: 0 | CF32: 0 | CG32: 0 | CH32: 0 | CI32: 0 | CJ32: 0 | CK32: 0 | CL32: 339
A33: Jäckle M. | B33: M | C33: 276 | CB33: 0 | CC33: 0 | CD33: 0 | CE33: 0 | CF33: 0 | CG33: 0 | CH33: 0 | CI33: 0 | CJ33: 0 | CK33: 0 | CL33: 276
A34: Jaki S. | B34: M | C34: 456 | N34: 0 | T34: 0 | X34: 0 | Y34: 1 | Z34: 0 | AA34: 0 | AD34: 0 | AE34: 0 | AF34: 0 | AG34: 1 | AH34: 0 | AI34: 0 | AJ34: 1 | AK34: 1 | AL34: 0 | AM34: 2 | BG34: 0 | CB34: 14 | CC34: 1 | CD34: 15 | CE34: 6 | CF34: 0 | CG34: 6 | CH34: 2 | CI34: 0 | CJ34: 17 | CK34: 6 | CL34: 473
A35: Jauch Jo. | B35: M | C35: 355 | BZ35: 0 | CB35: 0 | CC35: 1 | CD35: 1 | CE35: 0 | CF35: 0 | CG35: 0 | CH35: 0 | CI35: 0 | CJ35: 1 | CK35: 0 | CL35: 356
A36: Jauch Jürgen | B36: M | C36: 216 | CB36: 0 | CC36: 0 | CD36: 0 | CE36: 0 | CF36: 0 | CG36: 0 | CH36: 0 | CI36: 0 | CJ36: 0 | CK36: 0 | CL36: 216
A37: Kimmich Simeon | C37: 0 | BZ37: 0 | CB37: 0 | CC37: 1 | CD37: 1 | CE37: 0 | CF37: 0 | CG37: 0 | CH37: 0 | CI37: 0 | CJ37: 1 | CK37: 0 | CL37: 1
A38: Klausmann M. | B38: M | C38: 253 | CB38: 0 | CC38: 0 | CD38: 0 | CE38: 0 | CF38: 0 | CG38: 0 | CH38: 0 | CI38: 0 | CJ38: 0 | CK38: 0 | CL38: 253
A39: Kuner Matthias | C39: 2 | L39: 0 | O39: 0 | Q39: 0 | AC39: 0 | AU39: 0 | AX39: 0 | AZ39: 0 | BA39: 0 | BF39: 0 | BH39: 0 | BK39: 0 | BM39: 0 | BN39: 0 | BO39: 1 | BP39: 0 | BQ39: 1 | BS39: 1 | BT39: 0 | BV39: 0 | CB39: 5 | CC39: 11 | CD39: 16 | CE39: 0 | CF39: 3 | CG39: 3 | CH39: 3 | CI39: 0 | CJ39: 19 | CK39: 3 | CL39: 21
A40: Klein Daniel | B40: M | C40: 156 | J40: 0 | L40: 0 | N40: 0 | O40: 0 | Q40: 0 | T40: 0 | X40: 0 | BE40: 0 | BF40: 0 | BG40: 0 | BH40: 0 | BI40: 0 | BJ40: 0 | BK40: 0 | BL40: 0 | BM40: 0 | BN40: 0 | BO40: 0 | BP40: 0 | BQ40: 0 | BR40: 0 | BS40: 0 | BT40: 0 | BU40: 0 | BV40: 0 | BW40: 0 | BX40: 0 | BY40: 0 | BZ40: 0 | CB40: 1 | CC40: 22 | CD40: 23 | CE40: 0 | CF40: 0 | CG40: 0 | CH40: 6 | CI40: 0 | CJ40: 29 | CK40: 0 | CL40: 185
...

Sheet 15-16
E1: Saison 15/16
A2: Spieler | C2: Spiele bisher | D2: Freundschaftsspiele | S2: Pokalspiele | Y2: Punktspiele | CC2: Anzahl
D3: I | E3: I | F3: I | G3: I | H3: I | I3: I | J3: I | K3: I | M3: II | N3: II | O3: II | P3: II | U3: I | V3: II | Y3: I | Z3: I | AA3: I | AB3: I | AC3: I | AD3: I | AE3: I | AF3: I | AG3: I | AH3: I | AI3: I | AJ3: I | AK3: I | AL3: I | AM3: I | AN3: I | AO3: I | AP3: I | AQ3: I | AR3: I | AS3: I | AT3: I | AU3: I | AV3: I | AW3: I | AX3: I | AY3: I | AZ3: I | BA3: I | BB3: I | BC3: I | BD3: I | BE3: I | BF3: I | BH3: II | BI3: II | BJ3: II | BK3: II | BL3: II | BM3: II | BN3: II | BO3: II | BP3: II | BQ3: II | BR3: II | BS3: II | BT3: II | BU3: II | BV3: II | BW3: II | BX3: II | BY3: II | BZ3: II | CA3: II | CB3: II
D4: Sa, 18.07.15 SG Buchenberg/​Neuhausen : SGM Mariazell/​Locherhof | E4: Sa, 01.08.15 FC Dunningen : SGM Mariazell/​Locherhof | F4: Sa, 15.08.15 SGM Mariazell/​Locherhof : SV Seedorf II | G4: Di, 18.08.15 SGM Mariazell/​Locherhof : Spvgg 08 Schramberg | H4: Mi, 17.02.16 SV Gosheim : SGM Mariazell/​Locherhof | I4: Mi, 24.02.16 FV Tennenbronn 2 : SGM Mariazell/​Locherhof | J4: Sa, 27.02.16 SGM Aichhalden/​Rötenberg II : SGM Mariazell/​Locherhof | K4: Sa, 05.03.16 Spvgg 08 Schramberg : SGM Mariazell/​Locherhof | M4: Di, 04.08.15 SGM Mariazell/​Locherhof II : Spvgg 08 Schramberg II | N4: So, 09.08.15 SGM Mariazell/​Locherhof : Spvgg Bochingen II | O4: So, 06.03.16 Spvgg Stetten-Lackendorf : SGM Mariazell/​Locherhof II | P4: Sa, 12.03.16 SGM Mariazell/​Locherhof II : FC Weiler | U4: Di, 01.09.15 SGM Mariazell/​Locherhof : SV Gosheim | V4: Mi, 02.09.15 SGM riazell/​Locherhof II : SC Wellendingen | Y4: So, 23.08.15 FC Epfendorf : SGM Mariazell/​Locherhof | Z4: Do, 27.08.15 Spielfrei | AA4: So, 30.08.15 SGM Mariazell/​Locherhof : SV Herrenzimmern | AB4: So, 06.09.15 FV 08 Rottweil II : SGM Mariazell/​Locherhof | AC4: Sa, 12.09.15 SGM Mariazell/​Locherhof : SV Waldmössingen | AD4: Do, 17.09.15 FC Hardt : SGM Mariazell/​Locherhof | AE4: So, 20.09.15 SGM Mariazell/​Locherhof : SV Winzeln | AF4: So, 27.09.15 SC Lindenhof : SGM Mariazell/​Locherhof | AG4: Do, 01.10.15 SGM Mariazell/​Locherhof : SV Sulgen | AH4: So, 04.10.15 FC Dietingen : SGM Mariazell/​Locherhof | AI4: So, 11.10.15 SGM Mariazell/​Locherhof : SV Horgen | AJ4: So, 18.10.15 VfL Fluorn : SGM Mariazell/​Locherhof | AK4: So, 25.10.15 SGM Mariazell/​Locherhof : FC Suebia Rottweil | AL4: Sa, 31.10.15 SV Zimmern o.R. II : SGM Mariazell/​Locherhof | AM4: So, 08.11.15 SGM Mariazell/​Locherhof : SGM SV Beffendorf/​VfB Bösingen III | AN4: So, 15.11.15 SV Irslingen : SGM Mariazell/​Locherhof | AO4: Sa, 21.11.15 SGM Mariazell/​Locherhof : FSV Zepfenhan | AP4: Do, 17.03.16 SGM Mariazell/​Locherhof : FC Epfendorf | AQ4: So, 06.03.16 Spielfrei | AR4: So, 13.03.16 SV Herrenzimmern : SGM Mariazell/​Locherhof | AS4: So, 20.03.16 SGM Mariazell/​Locherhof : FV 08 Rottweil II | AT4: Sa, 26.03.16 SV Waldmössingen : SGM Mariazell/​Locherhof | AU4: Do, 31.03.16 SGM Mariazell/​Locherhof : FC Hardt | AV4: So, 03.04.16 SV Winzeln : SGM Mariazell/​Locherhof | AW4: So, 10.04.16 SGM Mariazell/​Locherhof : SC Lindenhof | AX4: So, 17.04.16 SV Sulgen : SGM Mariazell/​Locherhof | AY4: So, 24.04.16 SGM Mariazell/​Locherhof : FC Dietingen | AZ4: Do, 28.04.16 SV Horgen : SGM Mariazell/​Locherhof | BA4: Sa, 30.04.16 SGM Mariazell/​Locherhof : VfL Fluorn | BB4: So, 08.05.16 FC Suebia Rottweil : SGM Mariazell/​Locherhof | BC4: Sa, 14.05.16 SGM Mariazell/​Locherhof : SV Zimmern o.R. II | BD4: So, 22.05.16 SGM SV Beffendorf/​VfB Bösingen III : SGM Mariazell/​Locherhof | BE4: So, 29.05.16 SGM Mariazell/​Locherhof : SV Irslingen | BF4: So, 05.06.16 FSV Zepfenhan : SGM Mariazell/​Locherhof | BH4: So, 30.08.15 Spvgg Oberndorf II : SGM Mariazell/​Locherhof II | BI4: So, 13.09.15 SGM Mariazell/​Locherhof II : SV Winzeln II | BJ4: So, 20.09.15 FC Hardt II : SGM Mariazell/​Locherhof II | BK4: So, 27.09.15 SGM Mariazell/​Locherhof II : Spvgg Stetten-Lackendorf II | BL4: So, 04.10.15 SC Lindenhof II : SGM Mariazell/​Locherhof II | BM4: So, 11.10.15 SGM Mariazell/​Locherhof II : SV Sulgen II | BN4: So, 18.10.15 SV Herrenzimmern II : SGM Mariazell/​Locherhof II | BO4: So, 25.10.15 SGM Mariazell/​Locherhof II : FC Dunningen II | BP4: Sa, 21.11.15 FV Kickers Lauterbach II : SGM Mariazell/​Locherhof II | BQ4: So, 08.11.15 SGM Mariazell/​Locherhof II : SGM Aichhalden/​Rötenberg III | BR4: So, 15.11.15 SGM Mariazell/​Locherhof II : Spvgg Oberndorf II | BS4: So, 20.03.16 Spielfrei | BT4: So, 03.04.16 SV Winzeln II : SGM Mariazell/​Locherhof II | BU4: So, 10.04.16 SGM Mariazell/​Locherhof II : FC Hardt II | BV4: So, 17.04.16 Spvgg Stetten-Lackendorf II : SGM Mariazell/​Locherhof II | BW4: So, 24.04.16 SGM Mariazell/​Locherhof II : SC Lindenhof II | BX4: Mi, 04.05.16 SV Sulgen II : SGM Mariazell/​Locherhof II | BY4: So, 08.05.16 SGM Mariazell/​Locherhof II : SV Herrenzimmern II | BZ4: So, 22.05.16 FC Dunningen II : SGM Mariazell/​Locherhof II | CA4: So, 29.05.16 SGM Mariazell/​Locherhof II : FV Kickers Lauterbach II | CB4: So, 05.06.16 SGM Aichhalden/​Rötenberg III : SGM Mariazell/​Locherhof II | CC4: Punktspiele I | CD4: Punktspiele II | CE4: Punktspiele I+II | CF4: Tore Punktspiele I | CG4: Tore Punktspiele II | CH4: Tore Punktspiele I+II | CI4: Freundschaftssp. | CJ4: Tore Freundschaftssp. | CK4: Spiele | CL4: Tore | CM4: Spiele gesamt
A5: Aichele Thomas | B5: L | C5: 131 | CC5: 0 | CD5: 0 | CE5: 0 | CF5: 0 | CG5: 0 | CH5: 0 | CI5: 0 | CJ5: 0 | CK5: 0 | CL5: 0 | CM5: 131
A6: Auber Armin | B6: M | C6: 23 | BJ6: 0 | BK6: 0 | BO6: 0 | BP6: 0 | BV6: 1 | BY6: 0 | CA6: 0 | CC6: 0 | CD6: 7 | CE6: 7 | CF6: 0 | CG6: 1 | CH6: 1 | CI6: 0 | CJ6: 0 | CK6: 7 | CL6: 1 | CM6: 30
A7: Auber Axel | B7: M | C7: 382 | CC7: 0 | CD7: 0 | CE7: 0 | CF7: 0 | CG7: 0 | CH7: 0 | CI7: 0 | CJ7: 0 | CK7: 0 | CL7: 0 | CM7: 382
A8: Auber Manuel | C8: 0 | CB8: 0 | CC8: 0 | CD8: 1 | CE8: 1 | CF8: 0 | CG8: 0 | CH8: 0 | CI8: 0 | CJ8: 0 | CK8: 1 | CL8: 0 | CM8: 1
A9: Augstein M | B9: L | C9: 266 | BH9: 0 | BN9: 0 | BR9: 0 | CC9: 0 | CD9: 3 | CE9: 3 | CF9: 0 | CG9: 0 | CH9: 0 | CI9: 0 | CJ9: 0 | CK9: 3 | CL9: 0 | CM9: 269
A10: Bannert Dirk | B10: L | C10: 273 | CC10: 0 | CD10: 0 | CE10: 0 | CF10: 0 | CG10: 0 | CH10: 0 | CI10: 0 | CJ10: 0 | CK10: 0 | CL10: 0 | CM10: 273
A11: Bekir Kilic | B11: L | C11: 137 | CC11: 0 | CD11: 0 | CE11: 0 | CF11: 0 | CG11: 0 | CH11: 0 | CI11: 0 | CJ11: 0 | CK11: 0 | CL11: 0 | CM11: 137
A12: Benner, Florian | B12: M | C12: 59 | D12: 0 | M12: 0 | AD12: 0 | BI12: 0 | BJ12: 0 | BV12: 0 | CC12: 1 | CD12: 3 | CE12: 4 | CF12: 0 | CG12: 0 | CH12: 0 | CI12: 2 | CJ12: 0 | CK12: 6 | CL12: 0 | CM12: 65
A13: Binnig Andre | B13: L | C13: 100 | D13: 0 | F13: 1 | G13: 0 | H13: 0 | K13: 0 | M13: 0 | N13: 0 | U13: 0 | Y13: 0 | AA13: 1 | AB13: 0 | AC13: 1 | AD13: 0 | AE13: 0 | AF13: 0 | AG13: 0 | AH13: 0 | AI13: 0 | AJ13: 0 | AK13: 0 | AL13: 0 | AM13: 0 | AN13: 0 | AO13: 0 | AP13: 0 | AR13: 0 | AT13: 0 | AU13: 0 | AV13: 1 | AW13: 0 | AX13: 0 | AY13: 0 | AZ13: 0 | BA13: 0 | BB13: 0 | BC13: 0 | BD13: 0 | BE13: 0 | BF13: 0 | CC13: 31 | CD13: 0 | CE13: 31 | CF13: 3 | CG13: 0 | CH13: 3 | CI13: 8 | CJ13: 1 | CK13: 39 | CL13: 4 | CM13: 139
A14: Bosch M. | B14: L | C14: 420 | D14: 0 | F14: 0 | G14: 0 | K14: 0 | M14: 0 | N14: 0 | U14: 1 | Y14: 0 | AA14: 0 | AB14: 1 | AC14: 0 | AM14: 0 | AO14: 0 | BL14: 0 | BO14: 0 | BQ14: 0 | BR14: 1 | BX14: 0 | BY14: 0 | BZ14: 1 | CB14: 0 | CC14: 6 | CD14: 8 | CE14: 14 | CF14: 1 | CG14: 2 | CH14: 3 | CI14: 7 | CJ14: 1 | CK14: 21 | CL14: 4 | CM14: 441
A15: Broghammer Michael | B15: M | C15: 25 | CC15: 0 | CD15: 0 | CE15: 0 | CF15: 0 | CG15: 0 | CH15: 0 | CI15: 0 | CJ15: 0 | CK15: 0 | CL15: 0 | CM15: 25
A16: Coraci Davide | B16: L | C16: 41 | BH16: 0 | BK16: 1 | BN16: 0 | BU16: 0 | BV16: 0 | BY16: 0 | BZ16: 0 | CC16: 0 | CD16: 7 | CE16: 7 | CF16: 0 | CG16: 1 | CH16: 1 | CI16: 0 | CJ16: 0 | CK16: 7 | CL16: 1 | CM16: 48
A17: Czerny A | B17: M | C17: 227 | BR17: 0 | CC17: 0 | CD17: 1 | CE17: 1 | CF17: 0 | CG17: 0 | CH17: 0 | CI17: 0 | CJ17: 0 | CK17: 1 | CL17: 0 | CM17: 228
A18: Dereck Christian | B18: M | C18: 50 | H18: 0 | BH18: 0 | BI18: 0 | BJ18: 0 | BK18: 0 | BM18: 0 | BN18: 1 | BO18: 1 | BP18: 1 | BR18: 0 | BT18: 0 | BV18: 0 | BW18: 0 | BY18: 0 | BZ18: 0 | CA18: 0 | CB18: 2 | CC18: 0 | CD18: 16 | CE18: 16 | CF18: 0 | CG18: 5 | CH18: 5 | CI18: 1 | CJ18: 0 | CK18: 17 | CL18: 5 | CM18: 67
A19: Dold Markus | B19: M | C19: 90 | D19: 0 | G19: 0 | H19: 0 | K19: 0 | M19: 0 | U19: 0 | Y19: 0 | AA19: 0 | AB19: 1 | AC19: 0 | AD19: 0 | AE19: 0 | AF19: 0 | AG19: 0 | AH19: 0 | AI19: 0 | AJ19: 0 | AK19: 0 | AL19: 0 | AM19: 0 | AN19: 0 | AO19: 0 | AP19: 0 | AR19: 0 | AS19: 0 | AT19: 0 | AU19: 0 | AV19: 0 | AW19: 2 | AY19: 0 | AZ19: 0 | BB19: 0 | BD19: 0 | BE19: 0 | BF19: 0 | CC19: 29 | CD19: 0 | CE19: 29 | CF19: 3 | CG19: 0 | CH19: 3 | CI19: 6 | CJ19: 0 | CK19: 35 | CL19: 3 | CM19: 125
A20: Ebert D. | B20: M | C20: 385 | BY20: 1 | CC20: 0 | CD20: 1 | CE20: 1 | CF20: 0 | CG20: 1 | CH20: 1 | CI20: 0 | CJ20: 0 | CK20: 1 | CL20: 1 | CM20: 386
A21: Ebert M. | B21: M | C21: 234 | D21: 0 | H21: 0 | K21: 0 | M21: 0 | N21: 1 | AD21: 0 | AE21: 0 | AF21: 0 | AG21: 0 | AH21: 0 | AI21: 0 | AJ21: 0 | AN21: 0 | AO21: 0 | AP21: 0 | AR21: 0 | AS21: 0 | AU21: 0 | AV21: 0 | AW21: 0 | AX21: 0 | AY21: 0 | AZ21: 0 | BA21: 0 | BB21: 0 | BC21: 0 | BD21: 0 | BE21: 0 | BF21: 0 | BI21: 0 | CC21: 24 | CD21: 1 | CE21: 25 | CF21: 0 | CG21: 0 | CH21: 0 | CI21: 5 | CJ21: 1 | CK21: 30 | CL21: 1 | CM21: 264
A22: Engesser M. | B22: M | C22: 167 | CC22: 0 | CD22: 0 | CE22: 0 | CF22: 0 | CG22: 0 | CH22: 0 | CI22: 0 | CJ22: 0 | CK22: 0 | CL22: 0 | CM22: 167
A23: Ettwein Kevin | B23: L | C23: 8 | CC23: 0 | CD23: 0 | CE23: 0 | CF23: 0 | CG23: 0 | CH23: 0 | CI23: 0 | CJ23: 0 | CK23: 0 | CL23: 0 | CM23: 8
A24: Ettwein Dennis | B24: L | C24: 32 | CC24: 0 | CD24: 0 | CE24: 0 | CF24: 0 | CG24: 0 | CH24: 0 | CI24: 0 | CJ24: 0 | CK24: 0 | CL24: 0 | CM24: 32
A25: Ganter F. | B25: M | C25: 401 | CC25: 0 | CD25: 0 | CE25: 0 | CF25: 0 | CG25: 0 | CH25: 0 | CI25: 0 | CJ25: 0 | CK25: 0 | CL25: 0 | CM25: 401
A26: Ginter Colin | C26: 0 | BZ26: 0 | CC26: 0 | CD26: 1 | CE26: 1 | CF26: 0 | CG26: 0 | CH26: 0 | CI26: 0 | CJ26: 0 | CK26: 1 | CL26: 0 | CM26: 1
A27: Glase Rico | B27: M | C27: 41 | CC27: 0 | CD27: 0 | CE27: 0 | CF27: 0 | CG27: 0 | CH27: 0 | CI27: 0 | CJ27: 0 | CK27: 0 | CL27: 0 | CM27: 41
A28: Günter Ralf | B28: L | C28: 159 | D28: 0 | F28: 0 | G28: 0 | H28: 0 | K28: 0 | M28: 0 | N28: 0 | U28: 0 | Y28: 0 | AA28: 0 | AB28: 0 | AC28: 0 | AD28: 0 | AE28: 0 | AF28: 0 | AG28: 0 | AH28: 0 | AI28: 0 | AJ28: 0 | AK28: 1 | AL28: 1 | AM28: 0 | AN28: 0 | AO28: 0 | AP28: 0 | AR28: 0 | AS28: 0 | AT28: 0 | AU28: 0 | AV28: 0 | AW28: 0 | AX28: 0 | AY28: 0 | AZ28: 0 | BA28: 0 | BB28: 0 | BC28: 0 | BD28: 1 | BE28: 0 | BF28: 0 | CC28: 32 | CD28: 0 | CE28: 32 | CF28: 3 | CG28: 0 | CH28: 3 | CI28: 8 | CJ28: 0 | CK28: 40 | CL28: 3 | CM28: 199
A29: Haberstroh Benny | B29: M | C29: 19 | CC29: 0 | CD29: 0 | CE29: 0 | CF29: 0 | CG29: 0 | CH29: 0 | CI29: 0 | CJ29: 0 | CK29: 0 | CL29: 0 | CM29: 19
A30: Haberstroh Michael | B30: M | C30: 6 | BP30: 0 | CC30: 0 | CD30: 1 | CE30: 1 | CF30: 0 | CG30: 0 | CH30: 0 | CI30: 0 | CJ30: 0 | CK30: 1 | CL30: 0 | CM30: 7
A31: Haberstroh Raphael | B31: M | C31: 142 | D31: 0 | F31: 0 | G31: 0 | N31: 1 | U31: 0 | Y31: 0 | AA31: 0 | AB31: 0 | AC31: 0 | AD31: 0 | AE31: 0 | AF31: 1 | AH31: 1 | AI31: 0 | AJ31: 0 | AK31: 0 | AL31: 0 | AM31: 0 | AN31: 0 | AO31: 0 | AR31: 0 | AS31: 0 | AT31: 0 | AU31: 0 | AV31: 0 | AW31: 0 | AX31: 0 | AZ31: 0 | BA31: 0 | BB31: 0 | BC31: 1 | BD31: 0 | BE31: 0 | BF31: 0 | CC31: 29 | CD31: 0 | CE31: 29 | CF31: 3 | CG31: 0 | CH31: 3 | CI31: 5 | CJ31: 1 | CK31: 34 | CL31: 4 | CM31: 176
A32: Hauser Marcel | B32: L | C32: 27 | F32: 0 | G32: 0 | V32: 0 | BH32: 0 | BI32: 0 | BP32: 0 | BR32: 0 | BT32: 0 | BU32: 0 | BV32: 0 | BW32: 0 | BX32: 0 | BZ32: 0 | CA32: 0 | CB32: 0 | CC32: 0 | CD32: 12 | CE32: 12 | CF32: 0 | CG32: 0 | CH32: 0 | CI32: 3 | CJ32: 0 | CK32: 15 | CL32: 0 | CM32: 42
A33: Heilmann M. | B33: M | C33: 245 | BR33: 0 | CC33: 0 | CD33: 1 | CE33: 1 | CF33: 0 | CG33: 0 | CH33: 0 | CI33: 0 | CJ33: 0 | CK33: 1 | CL33: 0 | CM33: 246
A34: Hornikel A. | B34: M | C34: 339 | CC34: 0 | CD34: 0 | CE34: 0 | CF34: 0 | CG34: 0 | CH34: 0 | CI34: 0 | CJ34: 0 | CK34: 0 | CL34: 0 | CM34: 339
A35: Jäckle M. | B35: M | C35: 276 | CC35: 0 | CD35: 0 | CE35: 0 | CF35: 0 | CG35: 0 | CH35: 0 | CI35: 0 | CJ35: 0 | CK35: 0 | CL35: 0 | CM35: 276
A36: Jaki S. | B36: M | C36: 473 | AO36: 0 | BK36: 3 | BL36: 0 | BM36: 2 | BO36: 2 | BR36: 4 | BT36: 2 | BU36: 0 | BZ36: 2 | CA36: 0 | CB36: 1 | CC36: 1 | CD36: 10 | CE36: 11 | CF36: 0 | CG36: 16 | CH36: 16 | CI36: 0 | CJ36: 0 | CK36: 11 | CL36: 16 | CM36: 484
A37: Jauch Jo. | B37: M | C37: 356 | CC37: 0 | CD37: 0 | CE37: 0 | CF37: 0 | CG37: 0 | CH37: 0 | CI37: 0 | CJ37: 0 | CK37: 0 | CL37: 0 | CM37: 356
A38: Jauch Jürgen | B38: M | C38: 216 | CC38: 0 | CD38: 0 | CE38: 0 | CF38: 0 | CG38: 0 | CH38: 0 | CI38: 0 | CJ38: 0 | CK38: 0 | CL38: 0 | CM38: 216
A39: Kimmich Simeon | C39: 1 | F39: 0 | G39: 0 | N39: 0 | BI39: 0 | BJ39: 0 | BK39: 0 | BL39: 0 | BM39: 0 | BN39: 0 | BO39: 0 | BP39: 0 | BQ39: 0 | BR39: 0 | BT39: 0 | BU39: 0 | BV39: 0 | BW39: 0 | BX39: 0 | BY39: 0 | BZ39: 0 | CC39: 0 | CD39: 17 | CE39: 17 | CF39: 0 | CG39: 0 | CH39: 0 | CI39: 3 | CJ39: 0 | CK39: 20 | CL39: 0 | CM39: 21
A40: Klausmann M. | B40: M | C40: 253 | V40: 1 | BK40: 0 | BQ40: 0 | BY40: 0 | CC40: 0 | CD40: 3 | CE40: 3 | CF40: 0 | CG40: 0 | CH40: 0 | CI40: 1 | CJ40: 1 | CK40: 4 | CL40: 1 | CM40: 257
...

Sheet 17-18
E1: Saison 17/18
A2: Spieler | C2: Spiele bisher | D2: Freundschaftsspiele | T2: Pokalspiele | Y2: Punktspiele | BZ2: Anzahl
E3: I | F3: I | G3: I | H3: I | I3: I | J3: I | K3: I | L3: I | M3: I | O3: II | P3: II | T3: I | V3: II | Y3: I | Z3: I | AA3: I | AB3: I | AC3: I | AD3: I | AE3: I | AF3: I | AG3: I | AH3: I | AI3: I | AJ3: I | AK3: I | AL3: I | AM3: I | AN3: I | AO3: I | AP3: I | AQ3: I | AR3: I | AS3: I | AT3: I | AU3: I | AV3: I | AW3: I | AX3: I | AY3: I | AZ3: I | BA3: I | BB3: I | BD3: II | BE3: II | BF3: II | BG3: II | BH3: II | BI3: II | BJ3: II | BK3: II | BL3: II | BM3: II | BN3: II | BO3: II | BP3: II | BQ3: II | BR3: II | BS3: II | BT3: II | BU3: II | BV3: II | BW3: II | BX3: II | BY3: II
E4: So, 16.07.17 SG Lo/​Ma I : SV Tuningen | F4: Mi, 19.07.2017 SG Lo/​Ma I : FV Kickers Lauterbach | G4: Sa, 29.07.2017 SG Lo/​Ma I : Spvgg 08 Schramberg | H4: So, 06.08.2017 SG Lo/​Ma I : SC Kaltbrunn | I4: Sa, 03.02.18 Spvgg Stetten-Lackendorf : SG Lo/​Ma I | J4: Di, 06.02.18 SC Kaltbrunn: SG Lo/​Ma I | K4: So, 18.02.18 Spvgg 08 Schramberg : SG Lo/​Ma I | L4: Do, 22.02.18 FV Kickers Lauterbach : SG Lo/​Ma I | M4: Do, 01.03.18 FV Kickers Lauterbach : SG Lo/​Ma I | O4: Sa, 12.08.17 SG Lo/​Ma II : FC Hardt II | P4: So, 27.08.17 SV Horgen II : SG Lo/​Ma II | T4: Mi, 30.08.2017 FC Frittlingen : SG Lo/​Ma | V4: Mi, 30.08.17 SG Lo/​Ma II : Türk SV Schramberg | Y4: So, 20.08.17 Türk SV Schramberg : SG Lo/​Ma I | Z4: Mi, 23.08.17 SG Lo/​Ma I : SV Winzeln | AA4: Sa, 26.08.17 SGM Deißlingen/​Lauffen : SG Lo/​Ma I | AB4: So. 03.09.17 SG Lo/​Ma I : SPIELFREI | AC4: So. 10.09.17 SG Lo/​Ma I : SC Lindenhof | AD4: Do. 14.09.17 FC Hardt : SG Lo/​Ma I | AE4: So. 17.09.17 SG Lo/​Ma I : FC Suebia Rottweil | AF4: 24.09.17 SV Irslingen : SG Lo/​Ma I | AG4: 01.10.17 SG Lo/​Ma I : FC Epfendorf | AH4: 08.10.17 SV Harthausen : SG Lo/​Ma I | AI4: So. 15.10.17 SG Lo/​Ma I : SV Horgen | AJ4: So. 22.10.17 SV Waldmössingen : SG Lo/​Ma I | AK4: So. 29.10.17 SG MaLo I : Spvgg Oberndorf | AL4: So, 05.11.17 SV Herrenzimmern : SG Lo/​Ma I | AM4: So, 15.03.18 SG Lo/​Ma I : FSV Zepfenhan | AN4: So, 28.03.18 SG Lo/​Ma I : Türk SV Schramberg | AO4: Sa, 22.03.18 SV Winzeln : SG Lo/​Ma I | AP4: So, 11.03.18 SG Lo/​Ma I : SGM Deißlingen/​Lauffen | AQ4: So, 18.03.18 SG Lo/​Ma I : SPIELFREI | AR4: So, 25.03.18 SC Lindenhof : SG Lo/​Ma I | AS4: Sa, 31.03.18 SG Lo/​Ma I : FC Hardt | AT4: So, 08.04.18 FC Suebia Rottweil : SG Lo/​Ma I | AU4: So, 15.04.18 SG Lo/​Ma I : SV Irslingen | AV4: So, 22.04.18 FC Epfendorf : SG Lo/​Ma I | AW4: So, 29.04.18 SG Lo/​Ma I : SV Harthausen | AX4: Fr, 04.05.18 SV Horgen : SG Lo/​Ma I | AY4: So, 13.05.18 SG Lo/​Ma I : SV Waldmössingen | AZ4: So, 27.05.18 Spvgg Oberndorf : SG Lo/​Ma I | BA4: So, 03.06.18 SG Lo/​Ma I : SV Herrenzimmern | BB4: So, 10.06.18 FSV Zepfenhan : SG Lo/​Ma I | BD4: Fr, 08.09.2017 SG Lo/​Ma II : FC Göllsdorf II | BE4: So, 17.09.2017 SGM Aichhalden/​Rötenberg III : SG Lo/​Ma II | BF4: So, 24.09.2017 SG Lo/​Ma II : SV Sulgen II | BG4: So, 01.10.2017 SG Lo/​Ma II : SC Lindenhof II | BH4: Fr, 06.10.2017 FC Göllsdorf II : SG Lo/​Ma II | BI4: So, 15.10.2017 SG Lo/​Ma II : Spvgg 08 Schramberg II | BJ4: So, 22.10.2017 FC Dunningen II : SG Lo/​Ma II | BK4: So, 29.10.2017 SG Lo/​Ma II : Spvgg Stetten-Lackendorf I | BL4: So, 05.11.2017 SV Waldmössingen II : SG Lo/​Ma II | BM4: Fr, 13.04.2018 SG Lo/​Ma II : FV Kickers Lauterbach II | BN4: Do, 29.03.2018 SV Herrenzimmern II : SG Lo/​Ma II | BO4: Fr, 20.04.2018 SG Lo/​Ma II : SV Winzeln II | BP4: So, 25.03.2018 SC Lindenhof II : SG Lo/​Ma II | BQ4: So, 08.04.2018 Spvgg 08 Schramberg II : SG Lo/​Ma II | BR4: So, 15.04.2018 SG Lo/​Ma II : FC Dunningen II | BS4: So, 22.04.2018 Spvgg Stetten-Lackendorf II : SG Lo/​Ma II | BT4: So, 29.04.2018 SG Lo/​Ma II : SV Waldmössingen II | BU4: Do, 10.05.2018 FV Kickers Lauterbach II : SG Lo/​Ma II | BV4: So, 13.05.2018 SG Lo/​Ma II : SV Herrenzimmern II | BW4: So, 27.05.2018 SV Sulgen II : SG Lo/​Ma II | BX4: So, 03.06.2018 SG Lo/​Ma II : SGM Aichhalden/​Rötenberg III | BY4: So, 10.06.2018 SV Winzeln II : SG Lo/​Ma II | BZ4: Punktspiele I | CA4: Punktspiele II | CB4: Punktspiele I+II | CC4: Tore Punktspiele I | CD4: Tore Punktspiele II | CE4: Tore Punktspiele I+II | CF4: Freundschaftssp. | CG4: Tore Freundschaftssp. | CH4: Spiele | CI4: Tore | CJ4: Spiele gesamt
A5: Aichele Thomas | B5: L | C5: 131 | BZ5: 0 | CA5: 0 | CB5: 0 | CC5: 0 | CD5: 0 | CE5: 0 | CF5: 0 | CG5: 131 | CH5: 0 | CI5: 131 | CJ5: 131
A6: Auber Armin | B6: M | C6: 32 | BP6: 0 | BZ6: 0 | CA6: 1 | CB6: 1 | CC6: 0 | CD6: 0 | CE6: 0 | CF6: 0 | CG6: 32 | CH6: 1 | CI6: 32 | CJ6: 33
A7: Auber Axel | B7: M | C7: 382 | BZ7: 0 | CA7: 0 | CB7: 0 | CC7: 0 | CD7: 0 | CE7: 0 | CF7: 0 | CG7: 382 | CH7: 0 | CI7: 382 | CJ7: 382
A8: Auber Manuel | C8: 6 | BZ8: 0 | CA8: 0 | CB8: 0 | CC8: 0 | CD8: 0 | CE8: 0 | CF8: 0 | CG8: 6 | CH8: 0 | CI8: 6 | CJ8: 6
A9: Augstein M | B9: L | C9: 269 | V9: 0 | BK9: 0 | BL9: 0 | BY9: 0 | BZ9: 0 | CA9: 3 | CB9: 3 | CC9: 0 | CD9: 0 | CE9: 0 | CF9: 1 | CG9: 269 | CH9: 4 | CI9: 269 | CJ9: 273
A10: Bannert Dirk | B10: L | C10: 273 | BZ10: 0 | CA10: 0 | CB10: 0 | CC10: 0 | CD10: 0 | CE10: 0 | CF10: 0 | CG10: 273 | CH10: 0 | CI10: 273 | CJ10: 273
A11: Barwari Sarbast | C11: 13 | BN11: 0 | BP11: 0 | BQ11: 0 | BR11: 0 | BU11: 0 | BV11: 1 | BW11: 0 | BX11: 0 | BZ11: 0 | CA11: 8 | CB11: 8 | CC11: 0 | CD11: 1 | CE11: 1 | CF11: 0 | CG11: 13 | CH11: 8 | CI11: 14 | CJ11: 21
A12: Bea, Marc | C12: 0 | BQ12: 0 | BZ12: 0 | CA12: 1 | CB12: 1 | CC12: 0 | CD12: 0 | CE12: 0 | CF12: 0 | CG12: 0 | CH12: 1 | CI12: 0 | CJ12: 1
A13: Bekir Kilic | B13: L | C13: 137 | BZ13: 0 | CA13: 0 | CB13: 0 | CC13: 0 | CD13: 0 | CE13: 0 | CF13: 0 | CG13: 137 | CH13: 0 | CI13: 137 | CJ13: 137
A14: Benner, Florian | B14: M | C14: 65 | BI14: 0 | BJ14: 0 | BM14: 0 | BN14: 0 | BO14: 0 | BP14: 0 | BQ14: 0 | BR14: 0 | BS14: 0 | BT14: 0 | BV14: 0 | BW14: 0 | BX14: 0 | BY14: 0 | BZ14: 0 | CA14: 14 | CB14: 14 | CC14: 0 | CD14: 0 | CE14: 0 | CF14: 0 | CG14: 65 | CH14: 14 | CI14: 65 | CJ14: 79
A15: Binnig Andre | B15: L | C15: 158 | F15: 0 | H15: 0 | J15: 0 | O15: 0 | Y15: 0 | Z15: 0 | AA15: 0 | AC15: 0 | AD15: 0 | AE15: 0 | AF15: 0 | AH15: 0 | AI15: 0 | AK15: 0 | AL15: 0 | AN15: 0 | AO15: 0 | AP15: 0 | AR15: 0 | AS15: 0 | AT15: 0 | AU15: 0 | AZ15: 0 | BT15: 0 | BZ15: 19 | CA15: 1 | CB15: 20 | CC15: 0 | CD15: 0 | CE15: 0 | CF15: 4 | CG15: 158 | CH15: 24 | CI15: 158 | CJ15: 182
A16: Bosch M. | B16: L | C16: 462 | E16: 0 | J16: 0 | O16: 0 | P16: 0 | Y16: 0 | AX16: 0 | BD16: 0 | BE16: 0 | BG16: 0 | BI16: 0 | BJ16: 0 | BL16: 0 | BM16: 0 | BN16: 0 | BO16: 0 | BP16: 0 | BQ16: 0 | BR16: 0 | BS16: 0 | BT16: 0 | BU16: 0 | BX16: 0 | BY16: 0 | BZ16: 2 | CA16: 17 | CB16: 19 | CC16: 0 | CD16: 0 | CE16: 0 | CF16: 4 | CG16: 462 | CH16: 23 | CI16: 462 | CJ16: 485
A17: Broghammer Felix | C17: 1 | BF17: 0 | BZ17: 0 | CA17: 1 | CB17: 1 | CC17: 0 | CD17: 0 | CE17: 0 | CF17: 0 | CG17: 1 | CH17: 1 | CI17: 1 | CJ17: 2
A18: Broghammer Michael | B18: M | C18: 25 | BZ18: 0 | CA18: 0 | CB18: 0 | CC18: 0 | CD18: 0 | CE18: 0 | CF18: 0 | CG18: 25 | CH18: 0 | CI18: 25 | CJ18: 25
A19: Coraci Davide | B19: L | C19: 51 | P19: 0 | V19: 0 | BF19: 0 | BG19: 0 | BL19: 0 | BN19: 0 | BZ19: 0 | CA19: 4 | CB19: 4 | CC19: 0 | CD19: 0 | CE19: 0 | CF19: 2 | CG19: 51 | CH19: 6 | CI19: 51 | CJ19: 57
A20: Czerny A | B20: M | C20: 228 | BZ20: 0 | CA20: 0 | CB20: 0 | CC20: 0 | CD20: 0 | CE20: 0 | CF20: 0 | CG20: 228 | CH20: 0 | CI20: 228 | CJ20: 228
A21: Dereck Christian | B21: M | C21: 69 | BZ21: 0 | CA21: 0 | CB21: 0 | CC21: 0 | CD21: 0 | CE21: 0 | CF21: 0 | CG21: 69 | CH21: 0 | CI21: 69 | CJ21: 69
A22: Dold Markus | B22: M | C22: 152 | F22: 0 | BZ22: 0 | CA22: 0 | CB22: 0 | CC22: 0 | CD22: 0 | CE22: 0 | CF22: 1 | CG22: 152 | CH22: 1 | CI22: 152 | CJ22: 153
A23: Ebert D. | B23: M | C23: 387 | BZ23: 0 | CA23: 0 | CB23: 0 | CC23: 0 | CD23: 0 | CE23: 0 | CF23: 0 | CG23: 387 | CH23: 0 | CI23: 387 | CJ23: 387
